Workbook
Name iii: [1]Sheet3!$A$1:$C$48
Name kkk: [1]Sheet2!$C$7:$AN$74

Sheet Sheet1
B1: Target Values | C1: 8.15 | D1: 38.78 | E1: 26.21 | F1: 55.07 | G1: 3.81 | H1: 3.4 | I1: 152.23 | K1: CORE | L1: Mean | M1: 33085.65 | O1: SMR | P1: Mean | Q1: 9.23 | S1: Offet | T1: -5.5 | Y1: new sand coefficient | Z1: 15000 | AB1: Mean | AC1: 20
B2: Coefficient | C2: 0.5 | D2: 9999 | E2: 0.54 | F2: 0.029 | G2: 0.1 | H2: -0.01 | I2: 0.22 | L2: COEFF | M2: 9000 | P2: Coeff | Q2: -0.6 | T2: 8.18 | U2: 37.2 | V2: 25.95 | W2: 54.92 | X2: 4.23 | Y2: 3.47 | Z2: 163.6 | AA2: 7.1479406 | AB2: 0.0086457326 | AC2: 0.061799183 | AD2: 17.253805 | AE2: 0.0025950412 | AF2: 5225 | AG2: 107.90564 | AH2: 39972.4 | AI2: 14408.729 | AJ2: 15.310468
B3: Weight | C3: 0.1 | D3: 0 | E3: 0.45 | F3: 0.05 | G3: 0.3 | H3: 0.05 | I3: 0.05 | J3: 1 | T3: 20
B4: Correlation | C4: -0.61379631 | D4: -0.15075518 | E4: -0.34277831 | F4: -0.027485912 | G4: -0.51851612 | H4: -0.6862801 | I4: 0.32566726 | K4: 0.75987599 | O4: -0.3903536 | U4: 3 | Z4: 12 | AA4: 20 | AB4: 32 | AC4: 28
A6: date | B6: shift | C6: activeClay | D6: compactibility | E6: gcs | F6: gfnAfs | G6: loi | H6: moisture | I6: permeability | J6: sand_metal_ratio | K6: core_sand_ratio | L6: core_metal_ratio | M6: bentonite_predicted_kg | N6: fresh silica sand_predicted_kg | O6: return sand_predicted_kg | P6: water_predicted_kg | Q6: csi | R6: fss | S6: bentonite_predicted_kg1 | T6: Final Prediction | U6: Actual Bentonite | V6: P1 | W6: P2 | X6: Bent Actual | Y6: Bent Pred | Z6: MB CLAY | AA6: GCS | AB6: Moisture | AC6: LOI | AG6: activeClay | AH6: compactibility | AI6: gcs | AJ6: gfnAfs | AK6: loi | AL6: moisture | AM6: permeability | AN6: csi | AO6: sand_metal_ratio | AQ6: P1 | AR6: P2 | AT6: Dateshift
A7: 45413 | B7: Shift_10 | C7: 7.85 | D7: 38.6 | E7: 26.2 | F7: 52.64 | G7: 3.82 | H7: 3.292 | I7: 150.2 | J7: 10.148854 | K7: 0.0025907958 | L7: 0.026293609 | M7: 13.248319 | N7: 0.0025857588 | O7: 5225 | P7: 92.773344 | Q7: 6592.36 | R7: 0 | S7: 19.870809 | T7: =AVERAGE(AQ7:AR7) -> 8.4082839 | U7: =VLOOKUP($AT7,kkk,U$4,0) -> #N/A | V7: =M7+SUM(AG7:AO7)+$T$1+R7/$Z$1 -> 7.4225483 | W7: =M7+SUM(AG7:AO7)+$T$1+R7/$Z$1-AJ7-AM7 -> 2.7715295 | X7: =VLOOKUP($AT7,iii,3,0) -> #N/A | Y7: =VLOOKUP($AT7,iii,2,0) -> #N/A | Z7: =VLOOKUP($AT7,kkk,Z$4,0) -> #N/A | AA7: =VLOOKUP($AT7,kkk,AA$4,0) -> #N/A | AB7: =VLOOKUP($AT7,kkk,AB$4,0) -> #N/A | AC7: =VLOOKUP($AT7,kkk,AC$4,0) -> #N/A | AG7: =C$3*(C$1-C7)/C$2 -> 0.06 | AH7: =D$3*(D$1-D7)/D$2 -> 0 | AI7: =E$3*(E$1-E7)/E$2 -> 0.0083333333 | AJ7: =F$3*(F$1-F7)/F$2 -> 4.1896552 | AK7: =G$3*(G$1-G7)/G$2 -> -0.03 | AL7: =H$3*(H$1-H7)/H$2 -> -0.54 | AM7: =I$3*(I$1-I7)/I$2 -> 0.46136364 | AN7: =(Q7-$M$1)/$M$2 -> -2.9436989 | AO7: =(J7-$Q$1)/$Q$2 -> -1.5314242 | AQ7: =M7+SUM(AG7:AO7)+$T$1+R7/$Z$1 -> 7.4225483 | AR7: =S7+SUM(AG7:AO7)+$T$1+R7/$Z$1-AJ7-AM7 -> 9.3940195 | AT7: =A7&B7 -> 45413Shift_10
A8: 45413 | B8: Shift_11 | C8: 7.85 | D8: 38.6 | E8: 26.2 | F8: 52.64 | G8: 3.82 | H8: 3.292 | I8: 150.2 | J8: 10.433298 | K8: 0.0023279618 | L8: 0.02428832 | M8: 13.256022 | N8: 0.0025872603 | O8: 5225 | P8: 95.865134 | Q8: 6592.36 | R8: 0 | S8: 19.684352 | T8: =AVERAGE(AQ8:AR8) -> 7.8448332 | U8: =VLOOKUP($AT8,kkk,U$4,0) -> #N/A | V8: =M8+SUM(AG8:AO8)+$T$1+R8/$Z$1 -> 6.9561778 | W8: =M8+SUM(AG8:AO8)+$T$1+R8/$Z$1-AJ8-AM8 -> 2.3051589 | X8: =VLOOKUP($AT8,iii,3,0) -> #N/A | Y8: =VLOOKUP($AT8,iii,2,0) -> #N/A | Z8: =VLOOKUP($AT8,kkk,Z$4,0) -> #N/A | AA8: =VLOOKUP($AT8,kkk,AA$4,0) -> #N/A | AB8: =VLOOKUP($AT8,kkk,AB$4,0) -> #N/A | AC8: =VLOOKUP($AT8,kkk,AC$4,0) -> #N/A | AG8: =C$3*(C$1-C8)/C$2 -> 0.06 | AH8: =D$3*(D$1-D8)/D$2 -> 0 | AI8: =E$3*(E$1-E8)/E$2 -> 0.0083333333 | AJ8: =F$3*(F$1-F8)/F$2 -> 4.1896552 | AK8: =G$3*(G$1-G8)/G$2 -> -0.03 | AL8: =H$3*(H$1-H8)/H$2 -> -0.54 | AM8: =I$3*(I$1-I8)/I$2 -> 0.46136364 | AN8: =(Q8-$M$1)/$M$2 -> -2.9436989 | AO8: =(J8-$Q$1)/$Q$2 -> -2.0054973 | AQ8: =M8+SUM(AG8:AO8)+$T$1+R8/$Z$1 -> 6.9561778 | AR8: =S8+SUM(AG8:AO8)+$T$1+R8/$Z$1-AJ8-AM8 -> 8.7334887 | AT8: =A8&B8 -> 45413Shift_11
A9: 45413 | B9: Shift_12 | C9: 7.85 | D9: 37.857143 | E9: 26.314286 | F9: 52.64 | G9: 3.82 | H9: 3.2942857 | I9: 149 | J9: 10.460086 | K9: 0.0020637558 | L9: 0.021587064 | M9: 13.265803 | N9: 0.0025891679 | O9: 5225 | P9: 99.793456 | Q9: 6592.36 | R9: 0 | S9: 19.129038 | T9: =AVERAGE(AQ9:AR9) -> 7.5799744 | U9: =VLOOKUP($AT9,kkk,U$4,0) -> #N/A | V9: =M9+SUM(AG9:AO9)+$T$1+R9/$Z$1 -> 7.1102299 | W9: =M9+SUM(AG9:AO9)+$T$1+R9/$Z$1-AJ9-AM9 -> 2.1864839 | X9: =VLOOKUP($AT9,iii,3,0) -> #N/A | Y9: =VLOOKUP($AT9,iii,2,0) -> #N/A | Z9: =VLOOKUP($AT9,kkk,Z$4,0) -> #N/A | AA9: =VLOOKUP($AT9,kkk,AA$4,0) -> #N/A | AB9: =VLOOKUP($AT9,kkk,AB$4,0) -> #N/A | AC9: =VLOOKUP($AT9,kkk,AC$4,0) -> #N/A | AG9: =C$3*(C$1-C9)/C$2 -> 0.06 | AH9: =D$3*(D$1-D9)/D$2 -> 0 | AI9: =E$3*(E$1-E9)/E$2 -> -0.086904762 | AJ9: =F$3*(F$1-F9)/F$2 -> 4.1896552 | AK9: =G$3*(G$1-G9)/G$2 -> -0.03 | AL9: =H$3*(H$1-H9)/H$2 -> -0.52857143 | AM9: =I$3*(I$1-I9)/I$2 -> 0.73409091 | AN9: =(Q9-$M$1)/$M$2 -> -2.9436989 | AO9: =(J9-$Q$1)/$Q$2 -> -2.0501439 | AQ9: =M9+SUM(AG9:AO9)+$T$1+R9/$Z$1 -> 7.1102299 | AR9: =S9+SUM(AG9:AO9)+$T$1+R9/$Z$1-AJ9-AM9 -> 8.0497188 | AT9: =A9&B9 -> 45413Shift_12
A10: 45413 | B10: Shift_13 | C10: 8.025 | D10: 38.111111 | E10: 26.444444 | F10: 52.64 | G10: 3.94 | H10: 3.3177778 | I10: 149.44444 | J10: 10.262288 | K10: 0.001806692 | L10: 0.018540794 | M10: 13.311707 | N10: 0.0025981205 | O10: 5225 | P10: 118.21965 | Q10: 6592.36 | R10: 0 | S10: 17.414118 | T10: =AVERAGE(AQ10:AR10) -> 6.6386194 | U10: =VLOOKUP($AT10,kkk,U$4,0) -> #N/A | V10: =M10+SUM(AG10:AO10)+$T$1+R10/$Z$1 -> 6.9987819 | W10: =M10+SUM(AG10:AO10)+$T$1+R10/$Z$1-AJ10-AM10 -> 2.1760459 | X10: =VLOOKUP($AT10,iii,3,0) -> #N/A | Y10: =VLOOKUP($AT10,iii,2,0) -> #N/A | Z10: =VLOOKUP($AT10,kkk,Z$4,0) -> #N/A | AA10: =VLOOKUP($AT10,kkk,AA$4,0) -> #N/A | AB10: =VLOOKUP($AT10,kkk,AB$4,0) -> #N/A | AC10: =VLOOKUP($AT10,kkk,AC$4,0) -> #N/A | AG10: =C$3*(C$1-C10)/C$2 -> 0.025 | AH10: =D$3*(D$1-D10)/D$2 -> 0 | AI10: =E$3*(E$1-E10)/E$2 -> -0.19537037 | AJ10: =F$3*(F$1-F10)/F$2 -> 4.1896552 | AK10: =G$3*(G$1-G10)/G$2 -> -0.39 | AL10: =H$3*(H$1-H10)/H$2 -> -0.41111111 | AM10: =I$3*(I$1-I10)/I$2 -> 0.63308081 | AN10: =(Q10-$M$1)/$M$2 -> -2.9436989 | AO10: =(J10-$Q$1)/$Q$2 -> -1.7204806 | AQ10: =M10+SUM(AG10:AO10)+$T$1+R10/$Z$1 -> 6.9987819 | AR10: =S10+SUM(AG10:AO10)+$T$1+R10/$Z$1-AJ10-AM10 -> 6.2784569 | AT10: =A10&B10 -> 45413Shift_13
A11: 45413 | B11: Shift_14 | C11: 8.025 | D11: 38.111111 | E11: 26.444444 | F11: 52.64 | G11: 3.94 | H11: 3.3177778 | I11: 149.44444 | J11: 10.165435 | K11: 0.0031504097 | L11: 0.032025287 | M11: 13.304066 | N11: 0.0025966355 | O11: 5225 | P11: 115.15267 | Q11: 12938.975 | R11: 0 | S11: 17.657317 | T11: =AVERAGE(AQ11:AR11) -> 7.6229995 | U11: =VLOOKUP($AT11,kkk,U$4,0) -> #N/A | V11: =M11+SUM(AG11:AO11)+$T$1+R11/$Z$1 -> 7.8577423 | W11: =M11+SUM(AG11:AO11)+$T$1+R11/$Z$1-AJ11-AM11 -> 3.0350063 | X11: =VLOOKUP($AT11,iii,3,0) -> #N/A | Y11: =VLOOKUP($AT11,iii,2,0) -> #N/A | Z11: =VLOOKUP($AT11,kkk,Z$4,0) -> #N/A | AA11: =VLOOKUP($AT11,kkk,AA$4,0) -> #N/A | AB11: =VLOOKUP($AT11,kkk,AB$4,0) -> #N/A | AC11: =VLOOKUP($AT11,kkk,AC$4,0) -> #N/A | AG11: =C$3*(C$1-C11)/C$2 -> 0.025 | AH11: =D$3*(D$1-D11)/D$2 -> 0 | AI11: =E$3*(E$1-E11)/E$2 -> -0.19537037 | AJ11: =F$3*(F$1-F11)/F$2 -> 4.1896552 | AK11: =G$3*(G$1-G11)/G$2 -> -0.39 | AL11: =H$3*(H$1-H11)/H$2 -> -0.41111111 | AM11: =I$3*(I$1-I11)/I$2 -> 0.63308081 | AN11: =(Q11-$M$1)/$M$2 -> -2.2385195 | AO11: =(J11-$Q$1)/$Q$2 -> -1.5590591 | AQ11: =M11+SUM(AG11:AO11)+$T$1+R11/$Z$1 -> 7.8577423 | AR11: =S11+SUM(AG11:AO11)+$T$1+R11/$Z$1-AJ11-AM11 -> 7.3882566 | AT11: =A11&B11 -> 45413Shift_14
A12: 45413 | B12: Shift_15 | C12: 8.025 | D12: 38.1 | E12: 26.49 | F12: 56.5 | G12: 3.94 | H12: 3.318 | I12: 150.2 | J12: 10.253562 | K12: 0.0037037261 | L12: 0.037976385 | M12: 22.164113 | N12: 1.6949935 | O12: 5225 | P12: 95.866301 | Q12: 16927.48 | R12: 0 | S12: 17.754114 | T12: =AVERAGE(AQ12:AR12) -> 8.9474145 | U12: =VLOOKUP($AT12,kkk,U$4,0) -> #N/A | V12: =M12+SUM(AG12:AO12)+$T$1+R12/$Z$1 -> 10.150337 | W12: =M12+SUM(AG12:AO12)+$T$1+R12/$Z$1-AJ12-AM12 -> 12.154491 | X12: =VLOOKUP($AT12,iii,3,0) -> #N/A | Y12: =VLOOKUP($AT12,iii,2,0) -> #N/A | Z12: =VLOOKUP($AT12,kkk,Z$4,0) -> #N/A | AA12: =VLOOKUP($AT12,kkk,AA$4,0) -> #N/A | AB12: =VLOOKUP($AT12,kkk,AB$4,0) -> #N/A | AC12: =VLOOKUP($AT12,kkk,AC$4,0) -> #N/A | AG12: =C$3*(C$1-C12)/C$2 -> 0.025 | AH12: =D$3*(D$1-D12)/D$2 -> 0 | AI12: =E$3*(E$1-E12)/E$2 -> -0.23333333 | AJ12: =F$3*(F$1-F12)/F$2 -> -2.4655172 | AK12: =G$3*(G$1-G12)/G$2 -> -0.39 | AL12: =H$3*(H$1-H12)/H$2 -> -0.41 | AM12: =I$3*(I$1-I12)/I$2 -> 0.46136364 | AN12: =(Q12-$M$1)/$M$2 -> -1.7953522 | AO12: =(J12-$Q$1)/$Q$2 -> -1.7059366 | AQ12: =M12+SUM(AG12:AO12)+$T$1+R12/$Z$1 -> 10.150337 | AR12: =S12+SUM(AG12:AO12)+$T$1+R12/$Z$1-AJ12-AM12 -> 7.7444919 | AT12: =A12&B12 -> 45413Shift_15
A13: 45413 | B13: Shift_21 | C13: 8.2666667 | D13: 38 | E13: 26.466667 | F13: 56.5 | G13: 3.97 | H13: 3.3644444 | I13: 155.11111 | J13: 9.6936916 | K13: 0.0086689791 | L13: 0.084034409 | M13: 20.447873 | N13: 0.0025877073 | O13: 5225 | P13: 88.750736 | Q13: 38317.803 | R13: 0 | S13: 15.504178 | T13: =AVERAGE(AQ13:AR13) -> 9.8293991 | U13: =VLOOKUP($AT13,kkk,U$4,0) -> #N/A | V13: =M13+SUM(AG13:AO13)+$T$1+R13/$Z$1 -> 10.741089 | W13: =M13+SUM(AG13:AO13)+$T$1+R13/$Z$1-AJ13-AM13 -> 13.861404 | X13: =VLOOKUP($AT13,iii,3,0) -> #N/A | Y13: =VLOOKUP($AT13,iii,2,0) -> #N/A | Z13: =VLOOKUP($AT13,kkk,Z$4,0) -> #N/A | AA13: =VLOOKUP($AT13,kkk,AA$4,0) -> #N/A | AB13: =VLOOKUP($AT13,kkk,AB$4,0) -> #N/A | AC13: =VLOOKUP($AT13,kkk,AC$4,0) -> #N/A | AG13: =C$3*(C$1-C13)/C$2 -> -0.023333333 | AH13: =D$3*(D$1-D13)/D$2 -> 0 | AI13: =E$3*(E$1-E13)/E$2 -> -0.21388889 | AJ13: =F$3*(F$1-F13)/F$2 -> -2.4655172 | AK13: =G$3*(G$1-G13)/G$2 -> -0.48 | AL13: =H$3*(H$1-H13)/H$2 -> -0.17777778 | AM13: =I$3*(I$1-I13)/I$2 -> -0.65479798 | AN13: =(Q13-$M$1)/$M$2 -> 0.58135034 | AO13: =(J13-$Q$1)/$Q$2 -> -0.77281926 | AQ13: =M13+SUM(AG13:AO13)+$T$1+R13/$Z$1 -> 10.741089 | AR13: =S13+SUM(AG13:AO13)+$T$1+R13/$Z$1-AJ13-AM13 -> 8.9177095 | AT13: =A13&B13 -> 45413Shift_21
A14: 45413 | B14: Shift_22 | C14: 8.3125 | D14: 37.9 | E14: 26.57 | F14: 56.5 | G14: 3.97 | H14: 3.356 | I14: 154.7 | J14: 9.4669516 | K14: 0.0090871175 | L14: 0.086027302 | M14: 19.935125 | N14: 0.0025856961 | O14: 5225 | P14: 85.674037 | Q14: 41486.417 | R14: 0 | S14: 15.081048 | T14: =AVERAGE(AQ14:AR14) -> 10.000645 | U14: =VLOOKUP($AT14,kkk,U$4,0) -> #N/A | V14: =M14+SUM(AG14:AO14)+$T$1+R14/$Z$1 -> 10.914244 | W14: =M14+SUM(AG14:AO14)+$T$1+R14/$Z$1-AJ14-AM14 -> 13.941125 | X14: =VLOOKUP($AT14,iii,3,0) -> #N/A | Y14: =VLOOKUP($AT14,iii,2,0) -> #N/A | Z14: =VLOOKUP($AT14,kkk,Z$4,0) -> #N/A | AA14: =VLOOKUP($AT14,kkk,AA$4,0) -> #N/A | AB14: =VLOOKUP($AT14,kkk,AB$4,0) -> #N/A | AC14: =VLOOKUP($AT14,kkk,AC$4,0) -> #N/A | AG14: =C$3*(C$1-C14)/C$2 -> -0.0325 | AH14: =D$3*(D$1-D14)/D$2 -> 0 | AI14: =E$3*(E$1-E14)/E$2 -> -0.3 | AJ14: =F$3*(F$1-F14)/F$2 -> -2.4655172 | AK14: =G$3*(G$1-G14)/G$2 -> -0.48 | AL14: =H$3*(H$1-H14)/H$2 -> -0.22 | AM14: =I$3*(I$1-I14)/I$2 -> -0.56136364 | AN14: =(Q14-$M$1)/$M$2 -> 0.93341851 | AO14: =(J14-$Q$1)/$Q$2 -> -0.3949193 | AQ14: =M14+SUM(AG14:AO14)+$T$1+R14/$Z$1 -> 10.914244 | AR14: =S14+SUM(AG14:AO14)+$T$1+R14/$Z$1-AJ14-AM14 -> 9.0870471 | AT14: =A14&B14 -> 45413Shift_22
A15: 45413 | B15: Shift_23 | C15: 8.3125 | D15: 38.333333 | E15: 26.468889 | F15: 56.5 | G15: 3.97 | H15: 3.3511111 | I15: 155.44444 | J15: 9.3607146 | K15: 0.010299043 | L15: 0.096406398 | M15: 20.623535 | N15: 0.0025841094 | O15: 5225 | P15: 81.99612 | Q15: 48137.636 | R15: 0 | S15: 15.61591 | T15: =AVERAGE(AQ15:AR15) -> 11.503586 | U15: =VLOOKUP($AT15,kkk,U$4,0) -> #N/A | V15: =M15+SUM(AG15:AO15)+$T$1+R15/$Z$1 -> 12.409362 | W15: =M15+SUM(AG15:AO15)+$T$1+R15/$Z$1-AJ15-AM15 -> 15.605435 | X15: =VLOOKUP($AT15,iii,3,0) -> #N/A | Y15: =VLOOKUP($AT15,iii,2,0) -> #N/A | Z15: =VLOOKUP($AT15,kkk,Z$4,0) -> #N/A | AA15: =VLOOKUP($AT15,kkk,AA$4,0) -> #N/A | AB15: =VLOOKUP($AT15,kkk,AB$4,0) -> #N/A | AC15: =VLOOKUP($AT15,kkk,AC$4,0) -> #N/A | AG15: =C$3*(C$1-C15)/C$2 -> -0.0325 | AH15: =D$3*(D$1-D15)/D$2 -> 0 | AI15: =E$3*(E$1-E15)/E$2 -> -0.21574074 | AJ15: =F$3*(F$1-F15)/F$2 -> -2.4655172 | AK15: =G$3*(G$1-G15)/G$2 -> -0.48 | AL15: =H$3*(H$1-H15)/H$2 -> -0.24444444 | AM15: =I$3*(I$1-I15)/I$2 -> -0.73055556 | AN15: =(Q15-$M$1)/$M$2 -> 1.6724429 | AO15: =(J15-$Q$1)/$Q$2 -> -0.21785772 | AQ15: =M15+SUM(AG15:AO15)+$T$1+R15/$Z$1 -> 12.409362 | AR15: =S15+SUM(AG15:AO15)+$T$1+R15/$Z$1-AJ15-AM15 -> 10.59781 | AT15: =A15&B15 -> 45413Shift_23
A16: 45414 | B16: Shift_00 | C16: 8.4833333 | D16: 38.25 | E16: 26.54625 | F16: 56.5 | G16: 4.03 | H16: 3.3425 | I16: 156.125 | J16: 9.4288126 | K16: 0.014068135 | L16: 0.13264581 | M16: 19.758258 | N16: 0.0025847545 | O16: 5225 | P16: 84.156979 | Q16: 65953.397 | R16: 0 | S16: 14.605934 | T16: =AVERAGE(AQ16:AR16) -> 12.032966 | U16: =VLOOKUP($AT16,kkk,U$4,0) -> #N/A | V16: =M16+SUM(AG16:AO16)+$T$1+R16/$Z$1 -> 12.933756 | W16: =M16+SUM(AG16:AO16)+$T$1+R16/$Z$1-AJ16-AM16 -> 16.284501 | X16: =VLOOKUP($AT16,iii,3,0) -> #N/A | Y16: =VLOOKUP($AT16,iii,2,0) -> #N/A | Z16: =VLOOKUP($AT16,kkk,Z$4,0) -> #N/A | AA16: =VLOOKUP($AT16,kkk,AA$4,0) -> #N/A | AB16: =VLOOKUP($AT16,kkk,AB$4,0) -> #N/A | AC16: =VLOOKUP($AT16,kkk,AC$4,0) -> #N/A | AG16: =C$3*(C$1-C16)/C$2 -> -0.066666667 | AH16: =D$3*(D$1-D16)/D$2 -> 0 | AI16: =E$3*(E$1-E16)/E$2 -> -0.28020833 | AJ16: =F$3*(F$1-F16)/F$2 -> -2.4655172 | AK16: =G$3*(G$1-G16)/G$2 -> -0.66 | AL16: =H$3*(H$1-H16)/H$2 -> -0.2875 | AM16: =I$3*(I$1-I16)/I$2 -> -0.88522727 | AN16: =(Q16-$M$1)/$M$2 -> 3.6519719 | AO16: =(J16-$Q$1)/$Q$2 -> -0.33135433 | AQ16: =M16+SUM(AG16:AO16)+$T$1+R16/$Z$1 -> 12.933756 | AR16: =S16+SUM(AG16:AO16)+$T$1+R16/$Z$1-AJ16-AM16 -> 11.132176 | AT16: =A16&B16 -> 45414Shift_00
A17: 45414 | B17: Shift_01 | C17: 8.4833333 | D17: 38.25 | E17: 26.54625 | F17: 56.5 | G17: 4.03 | H17: 3.3425 | I17: 156.125 | J17: 9.4702057 | K17: 0.01707415 | L17: 0.16169571 | M17: 20.300215 | N17: 0.0025835993 | O17: 5225 | P17: 81.275199 | Q17: 80213.679 | R17: 0 | S17: 15.14168 | T17: =AVERAGE(AQ17:AR17) -> 14.087305 | U17: =VLOOKUP($AT17,kkk,U$4,0) -> #N/A | V17: =M17+SUM(AG17:AO17)+$T$1+R17/$Z$1 -> 14.9912 | W17: =M17+SUM(AG17:AO17)+$T$1+R17/$Z$1-AJ17-AM17 -> 18.341945 | X17: =VLOOKUP($AT17,iii,3,0) -> #N/A | Y17: =VLOOKUP($AT17,iii,2,0) -> #N/A | Z17: =VLOOKUP($AT17,kkk,Z$4,0) -> #N/A | AA17: =VLOOKUP($AT17,kkk,AA$4,0) -> #N/A | AB17: =VLOOKUP($AT17,kkk,AB$4,0) -> #N/A | AC17: =VLOOKUP($AT17,kkk,AC$4,0) -> #N/A | AG17: =C$3*(C$1-C17)/C$2 -> -0.066666667 | AH17: =D$3*(D$1-D17)/D$2 -> 0 | AI17: =E$3*(E$1-E17)/E$2 -> -0.28020833 | AJ17: =F$3*(F$1-F17)/F$2 -> -2.4655172 | AK17: =G$3*(G$1-G17)/G$2 -> -0.66 | AL17: =H$3*(H$1-H17)/H$2 -> -0.2875 | AM17: =I$3*(I$1-I17)/I$2 -> -0.88522727 | AN17: =(Q17-$M$1)/$M$2 -> 5.2364477 | AO17: =(J17-$Q$1)/$Q$2 -> -0.40034287 | AQ17: =M17+SUM(AG17:AO17)+$T$1+R17/$Z$1 -> 14.9912 | AR17: =S17+SUM(AG17:AO17)+$T$1+R17/$Z$1-AJ17-AM17 -> 13.18341 | AT17: =A17&B17 -> 45414Shift_01
A18: 45414 | B18: Shift_02 | C18: 8.4125 | D18: 38.25 | E18: 26.47875 | F18: 56.5 | G18: 4.03 | H18: 3.335 | I18: 154.5 | J18: 9.3277267 | K18: 0.018378364 | L18: 0.17142836 | M18: 21.255579 | N18: 0.0025840765 | O18: 5225 | P18: 81.287296 | Q18: 78972.76 | R18: 0 | S18: 16.197857 | T18: =AVERAGE(AQ18:AR18) -> 15.410237 | U18: =VLOOKUP($AT18,kkk,U$4,0) -> #N/A | V18: =M18+SUM(AG18:AO18)+$T$1+R18/$Z$1 -> 16.448384 | W18: =M18+SUM(AG18:AO18)+$T$1+R18/$Z$1-AJ18-AM18 -> 19.429811 | X18: =VLOOKUP($AT18,iii,3,0) -> #N/A | Y18: =VLOOKUP($AT18,iii,2,0) -> #N/A | Z18: =VLOOKUP($AT18,kkk,Z$4,0) -> #N/A | AA18: =VLOOKUP($AT18,kkk,AA$4,0) -> #N/A | AB18: =VLOOKUP($AT18,kkk,AB$4,0) -> #N/A | AC18: =VLOOKUP($AT18,kkk,AC$4,0) -> #N/A | AG18: =C$3*(C$1-C18)/C$2 -> -0.0525 | AH18: =D$3*(D$1-D18)/D$2 -> 0 | AI18: =E$3*(E$1-E18)/E$2 -> -0.22395833 | AJ18: =F$3*(F$1-F18)/F$2 -> -2.4655172 | AK18: =G$3*(G$1-G18)/G$2 -> -0.66 | AL18: =H$3*(H$1-H18)/H$2 -> -0.325 | AM18: =I$3*(I$1-I18)/I$2 -> -0.51590909 | AN18: =(Q18-$M$1)/$M$2 -> 5.0985678 | AO18: =(J18-$Q$1)/$Q$2 -> -0.1628778 | AQ18: =M18+SUM(AG18:AO18)+$T$1+R18/$Z$1 -> 16.448384 | AR18: =S18+SUM(AG18:AO18)+$T$1+R18/$Z$1-AJ18-AM18 -> 14.372089 | AT18: =A18&B18 -> 45414Shift_02
... A1151: 45566 | B1151: Shift_23 | C1151: 8.4733333 | D1151: 36.714286 | E1151: 28.252857 | F1151: 55.53 | G1151: 3.98 | H1151: 3.6742857 | I1151: 152.71429 | J1151: 8.837608 | K1151: 0.0085185201 | L1151: 0.075283342 | M1151: 13.316815 | N1151: 0.0025992715 | O1151: 5225 | P1151: 120.27004 | Q1151: 43828.393 | R1151: 14887.9 | S1151: 13.316815 | T1151: =AVERAGE(AQ1151:AR1151) -> 9.2997635 | U1151: =VLOOKUP($AT1151,kkk,U$4,0) -> #N/A | V1151: =M1151+SUM(AG1151:AO1151)+$T$1+R1151/$Z$1 -> 8.8481794 | W1151: =M1151+SUM(AG1151:AO1151)+$T$1+R1151/$Z$1-AJ1151-AM1151 -> 9.7513478 | X1151: =VLOOKUP($AT1151,iii,3,0) -> #N/A | Y1151: =VLOOKUP($AT1151,iii,2,0) -> #N/A | Z1151: =VLOOKUP($AT1151,kkk,Z$4,0) -> #N/A | AA1151: =VLOOKUP($AT1151,kkk,AA$4,0) -> #N/A | AB1151: =VLOOKUP($AT1151,kkk,AB$4,0) -> #N/A | AC1151: =VLOOKUP($AT1151,kkk,AC$4,0) -> #N/A | AG1151: =C$3*(C$1-C1151)/C$2 -> -0.064666667 | AH1151: =D$3*(D$1-D1151)/D$2 -> 0 | AI1151: =E$3*(E$1-E1151)/E$2 -> -1.702381 | AJ1151: =F$3*(F$1-F1151)/F$2 -> -0.79310345 | AK1151: =G$3*(G$1-G1151)/G$2 -> -0.51 | AL1151: =H$3*(H$1-H1151)/H$2 -> 1.3714286 | AM1151: =I$3*(I$1-I1151)/I$2 -> -0.11006494 | AN1151: =(Q1151-$M$1)/$M$2 -> 1.1936381 | AO1151: =(J1151-$Q$1)/$Q$2 -> 0.65398664 | AQ1151: =M1151+SUM(AG1151:AO1151)+$T$1+R1151/$Z$1 -> 8.8481794 | AR1151: =S1151+SUM(AG1151:AO1151)+$T$1+R1151/$Z$1-AJ1151-AM1151 -> 9.7513476 | AT1151: =A1151&B1151 -> 45566Shift_23
C1152: 7.93 | D1152: 36.85 | E1152: 25.8 | F1152: 53.57 | G1152: 3.72 | H1152: 3.25 | I1152: 166.69 | J1152: 7.8119718 | K1152: 0.0042406908 | L1152: 0.033128157 | M1152: 19.389795 | N1152: 0.0025831981 | O1152: 5225 | P1152: 81.258303 | Q1152: 21616.73 | R1152: 14314.103 | S1152: 20.844985 | T1152: =AVERAGE(AQ1152:AR1152) -> 16.216308 | U1152: =VLOOKUP($AT1152,kkk,U$4,0) -> #N/A | V1152: =M1152+SUM(AG1152:AO1152)+$T$1+R1152/$Z$1 -> 15.138635 | W1152: =M1152+SUM(AG1152:AO1152)+$T$1+R1152/$Z$1-AJ1152-AM1152 -> 15.838791 | X1152: =VLOOKUP($AT1152,iii,3,0) -> #N/A | Y1152: =VLOOKUP($AT1152,iii,2,0) -> #N/A | Z1152: =VLOOKUP($AT1152,kkk,Z$4,0) -> #N/A | AA1152: =VLOOKUP($AT1152,kkk,AA$4,0) -> #N/A | AB1152: =VLOOKUP($AT1152,kkk,AB$4,0) -> #N/A | AC1152: =VLOOKUP($AT1152,kkk,AC$4,0) -> #N/A | AG1152: =C$3*(C$1-C1152)/C$2 -> 0.044 | AH1152: =D$3*(D$1-D1152)/D$2 -> 0 | AI1152: =E$3*(E$1-E1152)/E$2 -> 0.34166667 | AJ1152: =F$3*(F$1-F1152)/F$2 -> 2.5862069 | AK1152: =G$3*(G$1-G1152)/G$2 -> 0.27 | AL1152: =H$3*(H$1-H1152)/H$2 -> -0.75 | AM1152: =I$3*(I$1-I1152)/I$2 -> -3.2863636 | AN1152: =(Q1152-$M$1)/$M$2 -> -1.2743244 | AO1152: =(J1152-$Q$1)/$Q$2 -> 2.3633804 | AQ1152: =M1152+SUM(AG1152:AO1152)+$T$1+R1152/$Z$1 -> 15.138635 | AR1152: =S1152+SUM(AG1152:AO1152)+$T$1+R1152/$Z$1-AJ1152-AM1152 -> 17.293981 | AT1152: =A1152&B1152 | AV1152: 25
T1153: =AVERAGE(AQ1153:AR1153) -> 88.881818 | U1153: =VLOOKUP($AT1153,kkk,U$4,0) -> #N/A | V1153: =M1153+SUM(AG1153:AO1153)+$T$1+R1153/$Z$1 -> 153.65482 | W1153: =M1153+SUM(AG1153:AO1153)+$T$1+R1153/$Z$1-AJ1153-AM1153 -> 24.108817 | X1153: =VLOOKUP($AT1153,iii,3,0) -> #N/A | Y1153: =VLOOKUP($AT1153,iii,2,0) -> #N/A | Z1153: =VLOOKUP($AT1153,kkk,Z$4,0) -> #N/A | AA1153: =VLOOKUP($AT1153,kkk,AA$4,0) -> #N/A | AB1153: =VLOOKUP($AT1153,kkk,AB$4,0) -> #N/A | AC1153: =VLOOKUP($AT1153,kkk,AC$4,0) -> #N/A | AG1153: =C$3*(C$1-C1153)/C$2 -> 1.63 | AH1153: =D$3*(D$1-D1153)/D$2 -> 0 | AI1153: =E$3*(E$1-E1153)/E$2 -> 21.841667 | AJ1153: =F$3*(F$1-F1153)/F$2 -> 94.948276 | AK1153: =G$3*(G$1-G1153)/G$2 -> 11.43 | AL1153: =H$3*(H$1-H1153)/H$2 -> -17 | AM1153: =I$3*(I$1-I1153)/I$2 -> 34.597727 | AN1153: =(Q1153-$M$1)/$M$2 -> -3.6761833 | AO1153: =(J1153-$Q$1)/$Q$2 -> 15.383333 | AQ1153: =M1153+SUM(AG1153:AO1153)+$T$1+R1153/$Z$1 -> 153.65482 | AR1153: =S1153+SUM(AG1153:AO1153)+$T$1+R1153/$Z$1-AJ1153-AM1153 -> 24.108817 | AT1153: =A1153&B1153
T1154: =AVERAGE(AQ1154:AR1154) -> 88.881818 | U1154: =VLOOKUP($AT1154,kkk,U$4,0) -> #N/A | V1154: =M1154+SUM(AG1154:AO1154)+$T$1+R1154/$Z$1 -> 153.65482 | W1154: =M1154+SUM(AG1154:AO1154)+$T$1+R1154/$Z$1-AJ1154-AM1154 -> 24.108817 | X1154: =VLOOKUP($AT1154,iii,3,0) -> #N/A | Y1154: =VLOOKUP($AT1154,iii,2,0) -> #N/A | Z1154: =VLOOKUP($AT1154,kkk,Z$4,0) -> #N/A | AA1154: =VLOOKUP($AT1154,kkk,AA$4,0) -> #N/A | AB1154: =VLOOKUP($AT1154,kkk,AB$4,0) -> #N/A | AC1154: =VLOOKUP($AT1154,kkk,AC$4,0) -> #N/A | AG1154: =C$3*(C$1-C1154)/C$2 -> 1.63 | AH1154: =D$3*(D$1-D1154)/D$2 -> 0 | AI1154: =E$3*(E$1-E1154)/E$2 -> 21.841667 | AJ1154: =F$3*(F$1-F1154)/F$2 -> 94.948276 | AK1154: =G$3*(G$1-G1154)/G$2 -> 11.43 | AL1154: =H$3*(H$1-H1154)/H$2 -> -17 | AM1154: =I$3*(I$1-I1154)/I$2 -> 34.597727 | AN1154: =(Q1154-$M$1)/$M$2 -> -3.6761833 | AO1154: =(J1154-$Q$1)/$Q$2 -> 15.383333 | AQ1154: =M1154+SUM(AG1154:AO1154)+$T$1+R1154/$Z$1 -> 153.65482 | AR1154: =S1154+SUM(AG1154:AO1154)+$T$1+R1154/$Z$1-AJ1154-AM1154 -> 24.108817 | AT1154: =A1154&B1154
T1155: =AVERAGE(AQ1155:AR1155) -> 88.881818 | U1155: =VLOOKUP($AT1155,kkk,U$4,0) -> #N/A | V1155: =M1155+SUM(AG1155:AO1155)+$T$1+R1155/$Z$1 -> 153.65482 | W1155: =M1155+SUM(AG1155:AO1155)+$T$1+R1155/$Z$1-AJ1155-AM1155 -> 24.108817 | X1155: =VLOOKUP($AT1155,iii,3,0) -> #N/A | Y1155: =VLOOKUP($AT1155,iii,2,0) -> #N/A | Z1155: =VLOOKUP($AT1155,kkk,Z$4,0) -> #N/A | AA1155: =VLOOKUP($AT1155,kkk,AA$4,0) -> #N/A | AB1155: =VLOOKUP($AT1155,kkk,AB$4,0) -> #N/A | AC1155: =VLOOKUP($AT1155,kkk,AC$4,0) -> #N/A | AG1155: =C$3*(C$1-C1155)/C$2 -> 1.63 | AH1155: =D$3*(D$1-D1155)/D$2 -> 0 | AI1155: =E$3*(E$1-E1155)/E$2 -> 21.841667 | AJ1155: =F$3*(F$1-F1155)/F$2 -> 94.948276 | AK1155: =G$3*(G$1-G1155)/G$2 -> 11.43 | AL1155: =H$3*(H$1-H1155)/H$2 -> -17 | AM1155: =I$3*(I$1-I1155)/I$2 -> 34.597727 | AN1155: =(Q1155-$M$1)/$M$2 -> -3.6761833 | AO1155: =(J1155-$Q$1)/$Q$2 -> 15.383333 | AQ1155: =M1155+SUM(AG1155:AO1155)+$T$1+R1155/$Z$1 -> 153.65482 | AR1155: =S1155+SUM(AG1155:AO1155)+$T$1+R1155/$Z$1-AJ1155-AM1155 -> 24.108817 | AT1155: =A1155&B1155
T1156: =AVERAGE(AQ1156:AR1156) -> 88.881818 | U1156: =VLOOKUP($AT1156,kkk,U$4,0) -> #N/A | V1156: =M1156+SUM(AG1156:AO1156)+$T$1+R1156/$Z$1 -> 153.65482 | W1156: =M1156+SUM(AG1156:AO1156)+$T$1+R1156/$Z$1-AJ1156-AM1156 -> 24.108817 | X1156: =VLOOKUP($AT1156,iii,3,0) -> #N/A | Y1156: =VLOOKUP($AT1156,iii,2,0) -> #N/A | Z1156: =VLOOKUP($AT1156,kkk,Z$4,0) -> #N/A | AA1156: =VLOOKUP($AT1156,kkk,AA$4,0) -> #N/A | AB1156: =VLOOKUP($AT1156,kkk,AB$4,0) -> #N/A | AC1156: =VLOOKUP($AT1156,kkk,AC$4,0) -> #N/A | AG1156: =C$3*(C$1-C1156)/C$2 -> 1.63 | AH1156: =D$3*(D$1-D1156)/D$2 -> 0 | AI1156: =E$3*(E$1-E1156)/E$2 -> 21.841667 | AJ1156: =F$3*(F$1-F1156)/F$2 -> 94.948276 | AK1156: =G$3*(G$1-G1156)/G$2 -> 11.43 | AL1156: =H$3*(H$1-H1156)/H$2 -> -17 | AM1156: =I$3*(I$1-I1156)/I$2 -> 34.597727 | AN1156: =(Q1156-$M$1)/$M$2 -> -3.6761833 | AO1156: =(J1156-$Q$1)/$Q$2 -> 15.383333 | AQ1156: =M1156+SUM(AG1156:AO1156)+$T$1+R1156/$Z$1 -> 153.65482 | AR1156: =S1156+SUM(AG1156:AO1156)+$T$1+R1156/$Z$1-AJ1156-AM1156 -> 24.108817 | AT1156: =A1156&B1156
A1157: 45698 | B1157: A | C1157: 7.93 | D1157: 38.9 | E1157: 25.57 | F1157: 54.73 | G1157: 3.51 | H1157: 3.29 | I1157: 166 | J1157: 7.9965084 | K1157: 0.002871692 | L1157: 0.022963509 | M1157: 24.264281 | N1157: 0.002585682 | O1157: 5225 | P1157: 81.333828 | Q1157: 15628 | R1157: 12676.247 | S1157: 22.041131 | T1157: =AVERAGE(AQ1157:AR1157) -> 18.269534 | U1157: =VLOOKUP($AT1157,kkk,U$4,0) -> #N/A | V1157: =M1157+SUM(AG1157:AO1157)+$T$1+R1157/$Z$1 -> 18.10944 | W1157: =M1157+SUM(AG1157:AO1157)+$T$1+R1157/$Z$1-AJ1157-AM1157 -> 20.652778 | X1157: =VLOOKUP($AT1157,iii,3,0) -> #N/A | Y1157: =VLOOKUP($AT1157,iii,2,0) -> #N/A | Z1157: =VLOOKUP($AT1157,kkk,Z$4,0) -> #N/A | AA1157: =VLOOKUP($AT1157,kkk,AA$4,0) -> #N/A | AB1157: =VLOOKUP($AT1157,kkk,AB$4,0) -> #N/A | AC1157: =VLOOKUP($AT1157,kkk,AC$4,0) -> #N/A | AG1157: =C$3*(C$1-C1157)/C$2 -> 0.044 | AH1157: =D$3*(D$1-D1157)/D$2 -> 0 | AI1157: =E$3*(E$1-E1157)/E$2 -> 0.53333333 | AJ1157: =F$3*(F$1-F1157)/F$2 -> 0.5862069 | AK1157: =G$3*(G$1-G1157)/G$2 -> 0.9 | AL1157: =H$3*(H$1-H1157)/H$2 -> -0.55 | AM1157: =I$3*(I$1-I1157)/I$2 -> -3.1295455 | AN1157: =(Q1157-$M$1)/$M$2 -> -1.9397389 | AO1157: =(J1157-$Q$1)/$Q$2 -> 2.0558194 | AQ1157: =M1157+SUM(AG1157:AO1157)+$T$1+R1157/$Z$1 -> 18.10944 | AR1157: =S1157+SUM(AG1157:AO1157)+$T$1+R1157/$Z$1-AJ1157-AM1157 -> 18.429628 | AT1157: =A1157&B1157 -> 45698A
A1158: 45698 | B1158: B | C1158: 8.46 | D1158: 38.17 | E1158: 25.44 | F1158: 55.14 | G1158: 3.51 | H1158: 3.5 | I1158: 163.17 | J1158: 7.811151 | K1158: 0.0031405221 | L1158: 0.024531093 | M1158: 14.965965 | N1158: 4.6750498 | O1158: 5225 | P1158: 81.262156 | Q1158: 11433.28 | R1158: 11607.67 | S1158: 13.231073 | T1158: =AVERAGE(AQ1158:AR1158) -> 10.007433 | U1158: =VLOOKUP($AT1158,kkk,U$4,0) -> #N/A | V1158: =M1158+SUM(AG1158:AO1158)+$T$1+R1158/$Z$1 -> 9.5713527 | W1158: =M1158+SUM(AG1158:AO1158)+$T$1+R1158/$Z$1-AJ1158-AM1158 -> 12.178406 | X1158: =VLOOKUP($AT1158,iii,3,0) -> #N/A | Y1158: =VLOOKUP($AT1158,iii,2,0) -> #N/A | Z1158: =VLOOKUP($AT1158,kkk,Z$4,0) -> #N/A | AA1158: =VLOOKUP($AT1158,kkk,AA$4,0) -> #N/A | AB1158: =VLOOKUP($AT1158,kkk,AB$4,0) -> #N/A | AC1158: =VLOOKUP($AT1158,kkk,AC$4,0) -> #N/A | AG1158: =C$3*(C$1-C1158)/C$2 -> -0.062 | AH1158: =D$3*(D$1-D1158)/D$2 -> 0 | AI1158: =E$3*(E$1-E1158)/E$2 -> 0.64166667 | AJ1158: =F$3*(F$1-F1158)/F$2 -> -0.12068966 | AK1158: =G$3*(G$1-G1158)/G$2 -> 0.9 | AL1158: =H$3*(H$1-H1158)/H$2 -> 0.5 | AM1158: =I$3*(I$1-I1158)/I$2 -> -2.4863636 | AN1158: =(Q1158-$M$1)/$M$2 -> -2.4058189 | AO1158: =(J1158-$Q$1)/$Q$2 -> 2.3647483 | AQ1158: =M1158+SUM(AG1158:AO1158)+$T$1+R1158/$Z$1 -> 9.5713527 | AR1158: =S1158+SUM(AG1158:AO1158)+$T$1+R1158/$Z$1-AJ1158-AM1158 -> 10.443513 | AT1158: =A1158&B1158 -> 45698B
A1159: 45699 | B1159: A | C1159: 8.07 | D1159: 37 | E1159: 26.41 | F1159: 54.02 | G1159: 3.76 | H1159: 3.44 | I1159: 159 | J1159: 8.1584936 | K1159: 0.004286335 | L1159: 0.034970037 | M1159: 13.622559 | N1159: 0.0025804918 | O1159: 5225 | P1159: 81.244866 | Q1159: 18580.28 | R1159: 14842.1 | S1159: 15.31095 | T1159: =AVERAGE(AQ1159:AR1159) -> 10.465552 | U1159: =VLOOKUP($AT1159,kkk,U$4,0) -> #N/A | V1159: =M1159+SUM(AG1159:AO1159)+$T$1+R1159/$Z$1 -> 9.7572105 | W1159: =M1159+SUM(AG1159:AO1159)+$T$1+R1159/$Z$1-AJ1159-AM1159 -> 9.485502 | X1159: =VLOOKUP($AT1159,iii,3,0) -> #N/A | Y1159: =VLOOKUP($AT1159,iii,2,0) -> #N/A | Z1159: =VLOOKUP($AT1159,kkk,Z$4,0) -> #N/A | AA1159: =VLOOKUP($AT1159,kkk,AA$4,0) -> #N/A | AB1159: =VLOOKUP($AT1159,kkk,AB$4,0) -> #N/A | AC1159: =VLOOKUP($AT1159,kkk,AC$4,0) -> #N/A | AG1159: =C$3*(C$1-C1159)/C$2 -> 0.016 | AH1159: =D$3*(D$1-D1159)/D$2 -> 0 | AI1159: =E$3*(E$1-E1159)/E$2 -> -0.16666667 | AJ1159: =F$3*(F$1-F1159)/F$2 -> 1.8103448 | AK1159: =G$3*(G$1-G1159)/G$2 -> 0.15 | AL1159: =H$3*(H$1-H1159)/H$2 -> 0.2 | AM1159: =I$3*(I$1-I1159)/I$2 -> -1.5386364 | AN1159: =(Q1159-$M$1)/$M$2 -> -1.6117078 | AO1159: =(J1159-$Q$1)/$Q$2 -> 1.785844 | AQ1159: =M1159+SUM(AG1159:AO1159)+$T$1+R1159/$Z$1 -> 9.7572105 | AR1159: =S1159+SUM(AG1159:AO1159)+$T$1+R1159/$Z$1-AJ1159-AM1159 -> 11.173893 | AT1159: =A1159&B1159 -> 45699A
A1160: 45699 | B1160: B | C1160: 8.18 | D1160: 37.73 | E1160: 26.27 | F1160: 55.46 | G1160: 3.94 | H1160: 3.4 | I1160: 166.73 | J1160: 8.5434998 | K1160: 0.0049126533 | L1160: 0.041971253 | M1160: 19.332181 | N1160: 0.0025835875 | O1160: 5225 | P1160: 82.229262 | Q1160: 25386.48 | R1160: 12034.4 | S1160: 15.103972 | T1160: =AVERAGE(AQ1160:AR1160) -> 10.379139 | U1160: =VLOOKUP($AT1160,kkk,U$4,0) -> #N/A | V1160: =M1160+SUM(AG1160:AO1160)+$T$1+R1160/$Z$1 -> 10.50931 | W1160: =M1160+SUM(AG1160:AO1160)+$T$1+R1160/$Z$1-AJ1160-AM1160 -> 14.477178 | X1160: =VLOOKUP($AT1160,iii,3,0) -> #N/A | Y1160: =VLOOKUP($AT1160,iii,2,0) -> #N/A | Z1160: =VLOOKUP($AT1160,kkk,Z$4,0) -> #N/A | AA1160: =VLOOKUP($AT1160,kkk,AA$4,0) -> #N/A | AB1160: =VLOOKUP($AT1160,kkk,AB$4,0) -> #N/A | AC1160: =VLOOKUP($AT1160,kkk,AC$4,0) -> #N/A | AG1160: =C$3*(C$1-C1160)/C$2 -> -0.006 | AH1160: =D$3*(D$1-D1160)/D$2 -> 0 | AI1160: =E$3*(E$1-E1160)/E$2 -> -0.05 | AJ1160: =F$3*(F$1-F1160)/F$2 -> -0.67241379 | AK1160: =G$3*(G$1-G1160)/G$2 -> -0.39 | AL1160: =H$3*(H$1-H1160)/H$2 -> 0 | AM1160: =I$3*(I$1-I1160)/I$2 -> -3.2954545 | AN1160: =(Q1160-$M$1)/$M$2 -> -0.85546333 | AO1160: =(J1160-$Q$1)/$Q$2 -> 1.1441671 | AQ1160: =M1160+SUM(AG1160:AO1160)+$T$1+R1160/$Z$1 -> 10.50931 | AR1160: =S1160+SUM(AG1160:AO1160)+$T$1+R1160/$Z$1-AJ1160-AM1160 -> 10.248969 | AT1160: =A1160&B1160 -> 45699B
A1161: 45700 | B1161: A | C1161: 7.91 | D1161: 37.9 | E1161: 25.97 | F1161: 54.24 | G1161: 3.59 | H1161: 3.33 | I1161: 158 | J1161: 8.745681 | K1161: 0.0076000205 | L1161: 0.066467355 | M1161: 19.775499 | N1161: 0.0025833938 | O1161: 5225 | P1161: 81.264279 | Q1161: 24668.96 | R1161: 14445.2 | S1161: 21.12322 | T1161: =AVERAGE(AQ1161:AR1161) -> 16.402219 | U1161: =VLOOKUP($AT1161,kkk,U$4,0) -> #N/A | V1161: =M1161+SUM(AG1161:AO1161)+$T$1+R1161/$Z$1 -> 15.788194 | W1161: =M1161+SUM(AG1161:AO1161)+$T$1+R1161/$Z$1-AJ1161-AM1161 -> 15.668523 | X1161: =VLOOKUP($AT1161,iii,3,0) -> #N/A | Y1161: =VLOOKUP($AT1161,iii,2,0) -> #N/A | Z1161: =VLOOKUP($AT1161,kkk,Z$4,0) -> #N/A | AA1161: =VLOOKUP($AT1161,kkk,AA$4,0) -> #N/A | AB1161: =VLOOKUP($AT1161,kkk,AB$4,0) -> #N/A | AC1161: =VLOOKUP($AT1161,kkk,AC$4,0) -> #N/A | AG1161: =C$3*(C$1-C1161)/C$2 -> 0.048 | AH1161: =D$3*(D$1-D1161)/D$2 -> 0 | AI1161: =E$3*(E$1-E1161)/E$2 -> 0.2 | AJ1161: =F$3*(F$1-F1161)/F$2 -> 1.4310345 | AK1161: =G$3*(G$1-G1161)/G$2 -> 0.66 | AL1161: =H$3*(H$1-H1161)/H$2 -> -0.35 | AM1161: =I$3*(I$1-I1161)/I$2 -> -1.3113636 | AN1161: =(Q1161-$M$1)/$M$2 -> -0.93518778 | AO1161: =(J1161-$Q$1)/$Q$2 -> 0.80719838 | AQ1161: =M1161+SUM(AG1161:AO1161)+$T$1+R1161/$Z$1 -> 15.788194 | AR1161: =S1161+SUM(AG1161:AO1161)+$T$1+R1161/$Z$1-AJ1161-AM1161 -> 17.016244 | AT1161: =A1161&B1161 -> 45700A
A1162: 45700 | B1162: B | C1162: 8.12 | D1162: 37.83 | E1162: 26.75 | F1162: 54.54 | G1162: 3.36 | H1162: 3.5 | I1162: 165.5 | J1162: 10.609484 | K1162: 0.011424031 | L1162: 0.12120308 | M1162: 17.864762 | N1162: 0.0025825044 | O1162: 5225 | P1162: 81.234674 | Q1162: 49288.08 | R1162: 8839.6 | S1162: 16.39693 | T1162: =AVERAGE(AQ1162:AR1162) -> 12.076225 | U1162: =VLOOKUP($AT1162,kkk,U$4,0) -> #N/A | V1162: =M1162+SUM(AG1162:AO1162)+$T$1+R1162/$Z$1 -> 11.759083 | W1162: =M1162+SUM(AG1162:AO1162)+$T$1+R1162/$Z$1-AJ1162-AM1162 -> 13.861199 | X1162: =VLOOKUP($AT1162,iii,3,0) -> #N/A | Y1162: =VLOOKUP($AT1162,iii,2,0) -> #N/A | Z1162: =VLOOKUP($AT1162,kkk,Z$4,0) -> #N/A | AA1162: =VLOOKUP($AT1162,kkk,AA$4,0) -> #N/A | AB1162: =VLOOKUP($AT1162,kkk,AB$4,0) -> #N/A | AC1162: =VLOOKUP($AT1162,kkk,AC$4,0) -> #N/A | AG1162: =C$3*(C$1-C1162)/C$2 -> 0.006 | AH1162: =D$3*(D$1-D1162)/D$2 -> 0 | AI1162: =E$3*(E$1-E1162)/E$2 -> -0.45 | AJ1162: =F$3*(F$1-F1162)/F$2 -> 0.9137931 | AK1162: =G$3*(G$1-G1162)/G$2 -> 1.35 | AL1162: =H$3*(H$1-H1162)/H$2 -> 0.5 | AM1162: =I$3*(I$1-I1162)/I$2 -> -3.0159091 | AN1162: =(Q1162-$M$1)/$M$2 -> 1.80027 | AO1162: =(J1162-$Q$1)/$Q$2 -> -2.2991402 | AQ1162: =M1162+SUM(AG1162:AO1162)+$T$1+R1162/$Z$1 -> 11.759083 | AR1162: =S1162+SUM(AG1162:AO1162)+$T$1+R1162/$Z$1-AJ1162-AM1162 -> 12.393367 | AT1162: =A1162&B1162 -> 45700B
A1163: 45701 | B1163: A | C1163: 7.98 | D1163: 37.78 | E1163: 25.39 | F1163: 53.8 | G1163: 3.63 | H1163: 3.44 | I1163: 159.67 | J1163: 7.6690195 | K1163: 0.0054081604 | L1163: 0.041475288 | M1163: 15.633207 | N1163: 0.0025814053 | O1163: 5225 | P1163: 81.200098 | Q1163: 25158.08 | R1163: 14092.4 | S1163: 18.029692 | T1163: =AVERAGE(AQ1163:AR1163) -> 15.698442 | U1163: =VLOOKUP($AT1163,kkk,U$4,0) -> #N/A | V1163: =M1163+SUM(AG1163:AO1163)+$T$1+R1163/$Z$1 -> 14.749573 | W1163: =M1163+SUM(AG1163:AO1163)+$T$1+R1163/$Z$1-AJ1163-AM1163 -> 14.250827 | X1163: =VLOOKUP($AT1163,iii,3,0) -> #N/A | Y1163: =VLOOKUP($AT1163,iii,2,0) -> #N/A | Z1163: =VLOOKUP($AT1163,kkk,Z$4,0) -> #N/A | AA1163: =VLOOKUP($AT1163,kkk,AA$4,0) -> #N/A | AB1163: =VLOOKUP($AT1163,kkk,AB$4,0) -> #N/A | AC1163: =VLOOKUP($AT1163,kkk,AC$4,0) -> #N/A | AG1163: =C$3*(C$1-C1163)/C$2 -> 0.034 | AH1163: =D$3*(D$1-D1163)/D$2 -> 0 | AI1163: =E$3*(E$1-E1163)/E$2 -> 0.68333333 | AJ1163: =F$3*(F$1-F1163)/F$2 -> 2.1896552 | AK1163: =G$3*(G$1-G1163)/G$2 -> 0.54 | AL1163: =H$3*(H$1-H1163)/H$2 -> 0.2 | AM1163: =I$3*(I$1-I1163)/I$2 -> -1.6909091 | AN1163: =(Q1163-$M$1)/$M$2 -> -0.88084111 | AO1163: =(J1163-$Q$1)/$Q$2 -> 2.6016341 | AQ1163: =M1163+SUM(AG1163:AO1163)+$T$1+R1163/$Z$1 -> 14.749573 | AR1163: =S1163+SUM(AG1163:AO1163)+$T$1+R1163/$Z$1-AJ1163-AM1163 -> 16.647312 | AT1163: =A1163&B1163 -> 45701A
A1164: 45701 | B1164: B | C1164: 8.01 | D1164: 37.45 | E1164: 25.52 | F1164: 55.38 | G1164: 3.67 | H1164: 3.3 | I1164: 155.09 | J1164: 7.1375286 | K1164: 0.0037305612 | L1164: 0.026626987 | M1164: 21.637655 | N1164: 0.0025843532 | O1164: 5225 | P1164: 81.293131 | Q1164: 17930.64 | R1164: 11289.6 | S1164: 19.914893 | T1164: =AVERAGE(AQ1164:AR1164) -> 17.763235 | U1164: =VLOOKUP($AT1164,kkk,U$4,0) -> #N/A | V1164: =M1164+SUM(AG1164:AO1164)+$T$1+R1164/$Z$1 -> 18.032375 | W1164: =M1164+SUM(AG1164:AO1164)+$T$1+R1164/$Z$1-AJ1164-AM1164 -> 19.216858 | X1164: =VLOOKUP($AT1164,iii,3,0) -> #N/A | Y1164: =VLOOKUP($AT1164,iii,2,0) -> #N/A | Z1164: =VLOOKUP($AT1164,kkk,Z$4,0) -> #N/A | AA1164: =VLOOKUP($AT1164,kkk,AA$4,0) -> #N/A | AB1164: =VLOOKUP($AT1164,kkk,AB$4,0) -> #N/A | AC1164: =VLOOKUP($AT1164,kkk,AC$4,0) -> #N/A | AG1164: =C$3*(C$1-C1164)/C$2 -> 0.028 | AH1164: =D$3*(D$1-D1164)/D$2 -> 0 | AI1164: =E$3*(E$1-E1164)/E$2 -> 0.575 | AJ1164: =F$3*(F$1-F1164)/F$2 -> -0.53448276 | AK1164: =G$3*(G$1-G1164)/G$2 -> 0.42 | AL1164: =H$3*(H$1-H1164)/H$2 -> -0.5 | AM1164: =I$3*(I$1-I1164)/I$2 -> -0.65 | AN1164: =(Q1164-$M$1)/$M$2 -> -1.68389 | AO1164: =(J1164-$Q$1)/$Q$2 -> 3.4874524 | AQ1164: =M1164+SUM(AG1164:AO1164)+$T$1+R1164/$Z$1 -> 18.032375 | AR1164: =S1164+SUM(AG1164:AO1164)+$T$1+R1164/$Z$1-AJ1164-AM1164 -> 17.494095 | AT1164: =A1164&B1164 -> 45701B
A1165: 45702 | B1165: A | C1165: 8.11 | D1165: 37.2 | E1165: 25.93 | F1165: 55.01 | G1165: 3.65 | H1165: 3.43 | I1165: 152.6 | J1165: 8.5083658 | K1165: 0.0042839202 | L1165: 0.036449161 | M1165: 15.357803 | N1165: 0.0025813231 | O1165: 5225 | P1165: 81.195831 | Q1165: 16982.32 | R1165: 14381.5 | S1165: 15.466471 | T1165: =AVERAGE(AQ1165:AR1165) -> 11.16538 | U1165: =VLOOKUP($AT1165,kkk,U$4,0) -> #N/A | V1165: =M1165+SUM(AG1165:AO1165)+$T$1+R1165/$Z$1 -> 11.120725 | W1165: =M1165+SUM(AG1165:AO1165)+$T$1+R1165/$Z$1-AJ1165-AM1165 -> 11.101367 | X1165: =VLOOKUP($AT1165,iii,3,0) -> #N/A | Y1165: =VLOOKUP($AT1165,iii,2,0) -> #N/A | Z1165: =VLOOKUP($AT1165,kkk,Z$4,0) -> #N/A | AA1165: =VLOOKUP($AT1165,kkk,AA$4,0) -> #N/A | AB1165: =VLOOKUP($AT1165,kkk,AB$4,0) -> #N/A | AC1165: =VLOOKUP($AT1165,kkk,AC$4,0) -> #N/A | AG1165: =C$3*(C$1-C1165)/C$2 -> 0.008 | AH1165: =D$3*(D$1-D1165)/D$2 -> 0 | AI1165: =E$3*(E$1-E1165)/E$2 -> 0.23333333 | AJ1165: =F$3*(F$1-F1165)/F$2 -> 0.10344828 | AK1165: =G$3*(G$1-G1165)/G$2 -> 0.48 | AL1165: =H$3*(H$1-H1165)/H$2 -> 0.15 | AM1165: =I$3*(I$1-I1165)/I$2 -> -0.084090909 | AN1165: =(Q1165-$M$1)/$M$2 -> -1.7892589 | AO1165: =(J1165-$Q$1)/$Q$2 -> 1.2027236 | AQ1165: =M1165+SUM(AG1165:AO1165)+$T$1+R1165/$Z$1 -> 11.120725 | AR1165: =S1165+SUM(AG1165:AO1165)+$T$1+R1165/$Z$1-AJ1165-AM1165 -> 11.210036 | AT1165: =A1165&B1165 -> 45702A
A1166: 45702 | B1166: B | C1166: 8.26 | D1166: 38.11 | E1166: 26.48 | F1166: 55.38 | G1166: 3.78 | H1166: 3.44 | I1166: 162.44 | J1166: 8.1870808 | K1166: 0.002877663 | L1166: 0.02355966 | M1166: 16.995995 | N1166: 0.0025834707 | O1166: 5225 | P1166: 81.221217 | Q1166: 13902.72 | R1166: 10466.4 | S1166: 13.567676 | T1166: =AVERAGE(AQ1166:AR1166) -> 8.7018886 | U1166: =VLOOKUP($AT1166,kkk,U$4,0) -> #N/A | V1166: =M1166+SUM(AG1166:AO1166)+$T$1+R1166/$Z$1 -> 8.9885795 | W1166: =M1166+SUM(AG1166:AO1166)+$T$1+R1166/$Z$1-AJ1166-AM1166 -> 11.843517 | X1166: =VLOOKUP($AT1166,iii,3,0) -> #N/A | Y1166: =VLOOKUP($AT1166,iii,2,0) -> #N/A | Z1166: =VLOOKUP($AT1166,kkk,Z$4,0) -> #N/A | AA1166: =VLOOKUP($AT1166,kkk,AA$4,0) -> #N/A | AB1166: =VLOOKUP($AT1166,kkk,AB$4,0) -> #N/A | AC1166: =VLOOKUP($AT1166,kkk,AC$4,0) -> #N/A | AG1166: =C$3*(C$1-C1166)/C$2 -> -0.022 | AH1166: =D$3*(D$1-D1166)/D$2 -> 0 | AI1166: =E$3*(E$1-E1166)/E$2 -> -0.225 | AJ1166: =F$3*(F$1-F1166)/F$2 -> -0.53448276 | AK1166: =G$3*(G$1-G1166)/G$2 -> 0.09 | AL1166: =H$3*(H$1-H1166)/H$2 -> 0.2 | AM1166: =I$3*(I$1-I1166)/I$2 -> -2.3204545 | AN1166: =(Q1166-$M$1)/$M$2 -> -2.1314367 | AO1166: =(J1166-$Q$1)/$Q$2 -> 1.7381987 | AQ1166: =M1166+SUM(AG1166:AO1166)+$T$1+R1166/$Z$1 -> 8.9885795 | AR1166: =S1166+SUM(AG1166:AO1166)+$T$1+R1166/$Z$1-AJ1166-AM1166 -> 8.4151978 | AT1166: =A1166&B1166 -> 45702B
T1167: =AVERAGE(AQ1167:AR1167) -> 88.881818 | U1167: =VLOOKUP($AT1167,kkk,U$4,0) -> #N/A | V1167: =M1167+SUM(AG1167:AO1167)+$T$1+R1167/$Z$1 -> 153.65482 | W1167: =M1167+SUM(AG1167:AO1167)+$T$1+R1167/$Z$1-AJ1167-AM1167 -> 24.108817 | X1167: =VLOOKUP($AT1167,iii,3,0) -> #N/A | Y1167: =VLOOKUP($AT1167,iii,2,0) -> #N/A | Z1167: =VLOOKUP($AT1167,kkk,Z$4,0) -> #N/A | AA1167: =VLOOKUP($AT1167,kkk,AA$4,0) -> #N/A | AB1167: =VLOOKUP($AT1167,kkk,AB$4,0) -> #N/A | AC1167: =VLOOKUP($AT1167,kkk,AC$4,0) -> #N/A | AG1167: =C$3*(C$1-C1167)/C$2 -> 1.63 | AH1167: =D$3*(D$1-D1167)/D$2 -> 0 | AI1167: =E$3*(E$1-E1167)/E$2 -> 21.841667 | AJ1167: =F$3*(F$1-F1167)/F$2 -> 94.948276 | AK1167: =G$3*(G$1-G1167)/G$2 -> 11.43 | AL1167: =H$3*(H$1-H1167)/H$2 -> -17 | AM1167: =I$3*(I$1-I1167)/I$2 -> 34.597727 | AN1167: =(Q1167-$M$1)/$M$2 -> -3.6761833 | AO1167: =(J1167-$Q$1)/$Q$2 -> 15.383333 | AQ1167: =M1167+SUM(AG1167:AO1167)+$T$1+R1167/$Z$1 -> 153.65482 | AR1167: =S1167+SUM(AG1167:AO1167)+$T$1+R1167/$Z$1-AJ1167-AM1167 -> 24.108817 | AT1167: =A1167&B1167
T1168: =AVERAGE(AQ1168:AR1168) -> 88.881818 | U1168: =VLOOKUP($AT1168,kkk,U$4,0) -> #N/A | V1168: =M1168+SUM(AG1168:AO1168)+$T$1+R1168/$Z$1 -> 153.65482 | W1168: =M1168+SUM(AG1168:AO1168)+$T$1+R1168/$Z$1-AJ1168-AM1168 -> 24.108817 | X1168: =VLOOKUP($AT1168,iii,3,0) -> #N/A | Y1168: =VLOOKUP($AT1168,iii,2,0) -> #N/A | Z1168: =VLOOKUP($AT1168,kkk,Z$4,0) -> #N/A | AA1168: =VLOOKUP($AT1168,kkk,AA$4,0) -> #N/A | AB1168: =VLOOKUP($AT1168,kkk,AB$4,0) -> #N/A | AC1168: =VLOOKUP($AT1168,kkk,AC$4,0) -> #N/A | AG1168: =C$3*(C$1-C1168)/C$2 -> 1.63 | AH1168: =D$3*(D$1-D1168)/D$2 -> 0 | AI1168: =E$3*(E$1-E1168)/E$2 -> 21.841667 | AJ1168: =F$3*(F$1-F1168)/F$2 -> 94.948276 | AK1168: =G$3*(G$1-G1168)/G$2 -> 11.43 | AL1168: =H$3*(H$1-H1168)/H$2 -> -17 | AM1168: =I$3*(I$1-I1168)/I$2 -> 34.597727 | AN1168: =(Q1168-$M$1)/$M$2 -> -3.6761833 | AO1168: =(J1168-$Q$1)/$Q$2 -> 15.383333 | AQ1168: =M1168+SUM(AG1168:AO1168)+$T$1+R1168/$Z$1 -> 153.65482 | AR1168: =S1168+SUM(AG1168:AO1168)+$T$1+R1168/$Z$1-AJ1168-AM1168 -> 24.108817 | AT1168: =A1168&B1168
T1169: =AVERAGE(AQ1169:AR1169) -> 88.881818 | U1169: =VLOOKUP($AT1169,kkk,U$4,0) -> #N/A | V1169: =M1169+SUM(AG1169:AO1169)+$T$1+R1169/$Z$1 -> 153.65482 | W1169: =M1169+SUM(AG1169:AO1169)+$T$1+R1169/$Z$1-AJ1169-AM1169 -> 24.108817 | X1169: =VLOOKUP($AT1169,iii,3,0) -> #N/A | Y1169: =VLOOKUP($AT1169,iii,2,0) -> #N/A | Z1169: =VLOOKUP($AT1169,kkk,Z$4,0) -> #N/A | AA1169: =VLOOKUP($AT1169,kkk,AA$4,0) -> #N/A | AB1169: =VLOOKUP($AT1169,kkk,AB$4,0) -> #N/A | AC1169: =VLOOKUP($AT1169,kkk,AC$4,0) -> #N/A | AG1169: =C$3*(C$1-C1169)/C$2 -> 1.63 | AH1169: =D$3*(D$1-D1169)/D$2 -> 0 | AI1169: =E$3*(E$1-E1169)/E$2 -> 21.841667 | AJ1169: =F$3*(F$1-F1169)/F$2 -> 94.948276 | AK1169: =G$3*(G$1-G1169)/G$2 -> 11.43 | AL1169: =H$3*(H$1-H1169)/H$2 -> -17 | AM1169: =I$3*(I$1-I1169)/I$2 -> 34.597727 | AN1169: =(Q1169-$M$1)/$M$2 -> -3.6761833 | AO1169: =(J1169-$Q$1)/$Q$2 -> 15.383333 | AQ1169: =M1169+SUM(AG1169:AO1169)+$T$1+R1169/$Z$1 -> 153.65482 | AR1169: =S1169+SUM(AG1169:AO1169)+$T$1+R1169/$Z$1-AJ1169-AM1169 -> 24.108817 | AT1169: =A1169&B1169
T1170: =AVERAGE(AQ1170:AR1170) -> 88.881818 | U1170: =VLOOKUP($AT1170,kkk,U$4,0) -> #N/A | V1170: =M1170+SUM(AG1170:AO1170)+$T$1+R1170/$Z$1 -> 153.65482 | W1170: =M1170+SUM(AG1170:AO1170)+$T$1+R1170/$Z$1-AJ1170-AM1170 -> 24.108817 | X1170: =VLOOKUP($AT1170,iii,3,0) -> #N/A | Y1170: =VLOOKUP($AT1170,iii,2,0) -> #N/A | Z1170: =VLOOKUP($AT1170,kkk,Z$4,0) -> #N/A | AA1170: =VLOOKUP($AT1170,kkk,AA$4,0) -> #N/A | AB1170: =VLOOKUP($AT1170,kkk,AB$4,0) -> #N/A | AC1170: =VLOOKUP($AT1170,kkk,AC$4,0) -> #N/A | AG1170: =C$3*(C$1-C1170)/C$2 -> 1.63 | AH1170: =D$3*(D$1-D1170)/D$2 -> 0 | AI1170: =E$3*(E$1-E1170)/E$2 -> 21.841667 | AJ1170: =F$3*(F$1-F1170)/F$2 -> 94.948276 | AK1170: =G$3*(G$1-G1170)/G$2 -> 11.43 | AL1170: =H$3*(H$1-H1170)/H$2 -> -17 | AM1170: =I$3*(I$1-I1170)/I$2 -> 34.597727 | AN1170: =(Q1170-$M$1)/$M$2 -> -3.6761833 | AO1170: =(J1170-$Q$1)/$Q$2 -> 15.383333 | AQ1170: =M1170+SUM(AG1170:AO1170)+$T$1+R1170/$Z$1 -> 153.65482 | AR1170: =S1170+SUM(AG1170:AO1170)+$T$1+R1170/$Z$1-AJ1170-AM1170 -> 24.108817 | AT1170: =A1170&B1170
T1171: =AVERAGE(AQ1171:AR1171) -> 88.881818 | U1171: =VLOOKUP($AT1171,kkk,U$4,0) -> #N/A | V1171: =M1171+SUM(AG1171:AO1171)+$T$1+R1171/$Z$1 -> 153.65482 | W1171: =M1171+SUM(AG1171:AO1171)+$T$1+R1171/$Z$1-AJ1171-AM1171 -> 24.108817 | X1171: =VLOOKUP($AT1171,iii,3,0) -> #N/A | Y1171: =VLOOKUP($AT1171,iii,2,0) -> #N/A | Z1171: =VLOOKUP($AT1171,kkk,Z$4,0) -> #N/A | AA1171: =VLOOKUP($AT1171,kkk,AA$4,0) -> #N/A | AB1171: =VLOOKUP($AT1171,kkk,AB$4,0) -> #N/A | AC1171: =VLOOKUP($AT1171,kkk,AC$4,0) -> #N/A | AG1171: =C$3*(C$1-C1171)/C$2 -> 1.63 | AH1171: =D$3*(D$1-D1171)/D$2 -> 0 | AI1171: =E$3*(E$1-E1171)/E$2 -> 21.841667 | AJ1171: =F$3*(F$1-F1171)/F$2 -> 94.948276 | AK1171: =G$3*(G$1-G1171)/G$2 -> 11.43 | AL1171: =H$3*(H$1-H1171)/H$2 -> -17 | AM1171: =I$3*(I$1-I1171)/I$2 -> 34.597727 | AN1171: =(Q1171-$M$1)/$M$2 -> -3.6761833 | AO1171: =(J1171-$Q$1)/$Q$2 -> 15.383333 | AQ1171: =M1171+SUM(AG1171:AO1171)+$T$1+R1171/$Z$1 -> 153.65482 | AR1171: =S1171+SUM(AG1171:AO1171)+$T$1+R1171/$Z$1-AJ1171-AM1171 -> 24.108817 | AT1171: =A1171&B1171
T1172: =AVERAGE(AQ1172:AR1172) -> 88.881818 | U1172: =VLOOKUP($AT1172,kkk,U$4,0) -> #N/A | V1172: =M1172+SUM(AG1172:AO1172)+$T$1+R1172/$Z$1 -> 153.65482 | W1172: =M1172+SUM(AG1172:AO1172)+$T$1+R1172/$Z$1-AJ1172-AM1172 -> 24.108817 | X1172: =VLOOKUP($AT1172,iii,3,0) -> #N/A | Y1172: =VLOOKUP($AT1172,iii,2,0) -> #N/A | Z1172: =VLOOKUP($AT1172,kkk,Z$4,0) -> #N/A | AA1172: =VLOOKUP($AT1172,kkk,AA$4,0) -> #N/A | AB1172: =VLOOKUP($AT1172,kkk,AB$4,0) -> #N/A | AC1172: =VLOOKUP($AT1172,kkk,AC$4,0) -> #N/A | AG1172: =C$3*(C$1-C1172)/C$2 -> 1.63 | AH1172: =D$3*(D$1-D1172)/D$2 -> 0 | AI1172: =E$3*(E$1-E1172)/E$2 -> 21.841667 | AJ1172: =F$3*(F$1-F1172)/F$2 -> 94.948276 | AK1172: =G$3*(G$1-G1172)/G$2 -> 11.43 | AL1172: =H$3*(H$1-H1172)/H$2 -> -17 | AM1172: =I$3*(I$1-I1172)/I$2 -> 34.597727 | AN1172: =(Q1172-$M$1)/$M$2 -> -3.6761833 | AO1172: =(J1172-$Q$1)/$Q$2 -> 15.383333 | AQ1172: =M1172+SUM(AG1172:AO1172)+$T$1+R1172/$Z$1 -> 153.65482 | AR1172: =S1172+SUM(AG1172:AO1172)+$T$1+R1172/$Z$1-AJ1172-AM1172 -> 24.108817 | AT1172: =A1172&B1172
T1173: =AVERAGE(AQ1173:AR1173) -> 88.881818 | U1173: =VLOOKUP($AT1173,kkk,U$4,0) -> #N/A | V1173: =M1173+SUM(AG1173:AO1173)+$T$1+R1173/$Z$1 -> 153.65482 | W1173: =M1173+SUM(AG1173:AO1173)+$T$1+R1173/$Z$1-AJ1173-AM1173 -> 24.108817 | X1173: =VLOOKUP($AT1173,iii,3,0) -> #N/A | Y1173: =VLOOKUP($AT1173,iii,2,0) -> #N/A | Z1173: =VLOOKUP($AT1173,kkk,Z$4,0) -> #N/A | AA1173: =VLOOKUP($AT1173,kkk,AA$4,0) -> #N/A | AB1173: =VLOOKUP($AT1173,kkk,AB$4,0) -> #N/A | AC1173: =VLOOKUP($AT1173,kkk,AC$4,0) -> #N/A | AG1173: =C$3*(C$1-C1173)/C$2 -> 1.63 | AH1173: =D$3*(D$1-D1173)/D$2 -> 0 | AI1173: =E$3*(E$1-E1173)/E$2 -> 21.841667 | AJ1173: =F$3*(F$1-F1173)/F$2 -> 94.948276 | AK1173: =G$3*(G$1-G1173)/G$2 -> 11.43 | AL1173: =H$3*(H$1-H1173)/H$2 -> -17 | AM1173: =I$3*(I$1-I1173)/I$2 -> 34.597727 | AN1173: =(Q1173-$M$1)/$M$2 -> -3.6761833 | AO1173: =(J1173-$Q$1)/$Q$2 -> 15.383333 | AQ1173: =M1173+SUM(AG1173:AO1173)+$T$1+R1173/$Z$1 -> 153.65482 | AR1173: =S1173+SUM(AG1173:AO1173)+$T$1+R1173/$Z$1-AJ1173-AM1173 -> 24.108817 | AT1173: =A1173&B1173
...

Sheet Sheet2
B1: =D1/3000 -> 0.55566667 | D1: 1667
G2: Lower Bound | H2: Upper Bound
B3: =IF(Sheet1!T1152>G3,IF(Sheet1!T1152<H3,Sheet1!T1152,H3),G3) -> 16.216308 | D3: 13.05 | G3: 5 | H3: 25
K4: =(44368.16-7150)/9000+(10.82-9.3)/0.6 -> 6.6686844
B5: =B3*B1+(1-B1)*D3 -> 14.809412 | D5: =AVERAGE(B3:D3) -> 14.633154
C7: =AVERAGE(B5:D5) -> 14.721283
A10: New Prediction | B10: =B3 -> 16.216308
A11: Aggressive Prediction | B11: =ROUND(B5,2) -> 14.81 | D11: activeClay | E11: compactibility | F11: gcs | G11: gfnAfs | H11: loi | I11: moisture | J11: permeability | K11: sand_metal_ratio | L11: core_sand_ratio | M11: core_metal_ratio | N11: bentonite_predicted_kg | O11: fresh silica sand_predicted_kg | P11: return sand_predicted_kg | Q11: water_predicted_kg | R11: csi | S11: fss | T11: bentonite_predicted_kg1
A12: Conservative Prediction | B12: =ROUND(D5,2) -> 14.63 | D12: 8.39 | E12: 37.57 | F12: 27.1 | G12: 55.83 | H12: 3.96 | I12: 3.55 | J12: 167.43 | K12: 7.9256593 | L12: 0.0063356025 | M12: 0.050213827 | N12: 16.958459 | O12: 0.0025945682 | P12: 5225 | Q12: 96.356728 | R12: 20414.324 | S12: 8652.3395 | T12: 13.293036
A13: Ensemble Prediction | B13: =ROUND(C7,2) -> 14.72
A14: Core | B14: =ROUND(Sheet1!Q1152,2) -> 21616.73
A15: SMR | B15: =ROUND(Sheet1!J1152,2) -> 7.81
A16: Offset | B16: =Sheet1!T1 -> -5.5
A17: Boxes | B17: =D1 -> 1667
A18: Active Clay mean | B18: =ROUND(Sheet1!C1152,2) -> 7.93
A19: GCS mean | B19: =ROUND(Sheet1!E1152,2) -> 25.8
A20: Shift Predcition | B20: =D3 -> 13.05

Sheet Sheet1 (2)
B1: Target Values | C1: 8.15 | D1: 38.78 | E1: 26.21 | F1: 55.07 | G1: 3.81 | H1: 3.4 | I1: 152.23 | K1: CORE | L1: Mean | M1: 33085.65 | O1: SMR | P1: Mean | Q1: 9.23 | S1: Offet | T1: ='Sheet2 (2)'!B16 -> -9.5 | Y1: new sand coefficient | Z1: 15000 | AB1: Mean | AC1: 20
B2: Coefficient | C2: 0.5 | D2: 9999 | E2: 0.54 | F2: 0.029 | G2: 0.1 | H2: -0.01 | I2: 0.22 | L2: COEFF | M2: 9000 | P2: Coeff | Q2: -0.6 | T2: 8.18 | U2: 37.2 | V2: 25.95 | W2: 54.92 | X2: 4.23 | Y2: 3.47 | Z2: 163.6 | AA2: 7.1479406 | AB2: 0.0086457326 | AC2: 0.061799183 | AD2: 17.253805 | AE2: 0.0025950412 | AF2: 5225 | AG2: 107.90564 | AH2: 39972.4 | AI2: 14408.729 | AJ2: 15.310468
B3: Weight | C3: 0.1 | D3: 0 | E3: 0.45 | F3: 0.05 | G3: 0.3 | H3: 0.05 | I3: 0.05 | J3: 1 | T3: 20
B4: Correlation | C4: -0.61379631 | D4: -0.15075518 | E4: -0.34277831 | F4: -0.027485912 | G4: -0.51851612 | H4: -0.6862801 | I4: 0.32566726 | K4: 0.75987599 | O4: -0.3903536 | U4: 3 | Z4: 12 | AA4: 20 | AB4: 32 | AC4: 28
A6: date | B6: shift | C6: activeClay | D6: compactibility | E6: gcs | F6: gfnAfs | G6: loi | H6: moisture | I6: permeability | J6: sand_metal_ratio | K6: core_sand_ratio | L6: core_metal_ratio | M6: bentonite_predicted_kg | N6: fresh silica sand_predicted_kg | O6: return sand_predicted_kg | P6: water_predicted_kg | Q6: csi | R6: fss | S6: bentonite_predicted_kg1 | T6: Final Prediction | U6: Actual Bentonite | V6: P1 | W6: P2 | X6: Bent Actual | Y6: Bent Pred | Z6: MB CLAY | AA6: GCS | AB6: Moisture | AC6: LOI | AG6: activeClay | AH6: compactibility | AI6: gcs | AJ6: gfnAfs | AK6: loi | AL6: moisture | AM6: permeability | AN6: csi | AO6: sand_metal_ratio | AQ6: P1 | AR6: P2 | AT6: Dateshift
A7: 45413 | B7: Shift_10 | C7: 7.85 | D7: 38.6 | E7: 26.2 | F7: 52.64 | G7: 3.82 | H7: 3.292 | I7: 150.2 | J7: 10.148854 | K7: 0.0025907958 | L7: 0.026293609 | M7: 13.248319 | N7: 0.0025857588 | O7: 5225 | P7: 92.773344 | Q7: 6592.36 | R7: 0 | S7: 19.870809 | T7: =AVERAGE(AQ7:AR7) -> 4.4082839 | U7: =VLOOKUP($AT7,kkk,U$4,0) -> #N/A | V7: =M7+SUM(AG7:AO7)+$T$1+R7/$Z$1 -> 3.4225483 | W7: =M7+SUM(AG7:AO7)+$T$1+R7/$Z$1-AJ7-AM7 -> -1.2284705 | X7: =VLOOKUP($AT7,iii,3,0) -> #N/A | Y7: =VLOOKUP($AT7,iii,2,0) -> #N/A | Z7: =VLOOKUP($AT7,kkk,Z$4,0) -> #N/A | AA7: =VLOOKUP($AT7,kkk,AA$4,0) -> #N/A | AB7: =VLOOKUP($AT7,kkk,AB$4,0) -> #N/A | AC7: =VLOOKUP($AT7,kkk,AC$4,0) -> #N/A | AG7: =C$3*(C$1-C7)/C$2 -> 0.06 | AH7: =D$3*(D$1-D7)/D$2 -> 0 | AI7: =E$3*(E$1-E7)/E$2 -> 0.0083333333 | AJ7: =F$3*(F$1-F7)/F$2 -> 4.1896552 | AK7: =G$3*(G$1-G7)/G$2 -> -0.03 | AL7: =H$3*(H$1-H7)/H$2 -> -0.54 | AM7: =I$3*(I$1-I7)/I$2 -> 0.46136364 | AN7: =(Q7-$M$1)/$M$2 -> -2.9436989 | AO7: =(J7-$Q$1)/$Q$2 -> -1.5314242 | AQ7: =M7+SUM(AG7:AO7)+$T$1+R7/$Z$1 -> 3.4225483 | AR7: =S7+SUM(AG7:AO7)+$T$1+R7/$Z$1-AJ7-AM7 -> 5.3940195 | AT7: =A7&B7 -> 45413Shift_10
A8: 45413 | B8: Shift_11 | C8: 7.85 | D8: 38.6 | E8: 26.2 | F8: 52.64 | G8: 3.82 | H8: 3.292 | I8: 150.2 | J8: 10.433298 | K8: 0.0023279618 | L8: 0.02428832 | M8: 13.256022 | N8: 0.0025872603 | O8: 5225 | P8: 95.865134 | Q8: 6592.36 | R8: 0 | S8: 19.684352 | T8: =AVERAGE(AQ8:AR8) -> 3.8448332 | U8: =VLOOKUP($AT8,kkk,U$4,0) -> #N/A | V8: =M8+SUM(AG8:AO8)+$T$1+R8/$Z$1 -> 2.9561778 | W8: =M8+SUM(AG8:AO8)+$T$1+R8/$Z$1-AJ8-AM8 -> -1.6948411 | X8: =VLOOKUP($AT8,iii,3,0) -> #N/A | Y8: =VLOOKUP($AT8,iii,2,0) -> #N/A | Z8: =VLOOKUP($AT8,kkk,Z$4,0) -> #N/A | AA8: =VLOOKUP($AT8,kkk,AA$4,0) -> #N/A | AB8: =VLOOKUP($AT8,kkk,AB$4,0) -> #N/A | AC8: =VLOOKUP($AT8,kkk,AC$4,0) -> #N/A | AG8: =C$3*(C$1-C8)/C$2 -> 0.06 | AH8: =D$3*(D$1-D8)/D$2 -> 0 | AI8: =E$3*(E$1-E8)/E$2 -> 0.0083333333 | AJ8: =F$3*(F$1-F8)/F$2 -> 4.1896552 | AK8: =G$3*(G$1-G8)/G$2 -> -0.03 | AL8: =H$3*(H$1-H8)/H$2 -> -0.54 | AM8: =I$3*(I$1-I8)/I$2 -> 0.46136364 | AN8: =(Q8-$M$1)/$M$2 -> -2.9436989 | AO8: =(J8-$Q$1)/$Q$2 -> -2.0054973 | AQ8: =M8+SUM(AG8:AO8)+$T$1+R8/$Z$1 -> 2.9561778 | AR8: =S8+SUM(AG8:AO8)+$T$1+R8/$Z$1-AJ8-AM8 -> 4.7334887 | AT8: =A8&B8 -> 45413Shift_11
A9: 45413 | B9: Shift_12 | C9: 7.85 | D9: 37.857143 | E9: 26.314286 | F9: 52.64 | G9: 3.82 | H9: 3.2942857 | I9: 149 | J9: 10.460086 | K9: 0.0020637558 | L9: 0.021587064 | M9: 13.265803 | N9: 0.0025891679 | O9: 5225 | P9: 99.793456 | Q9: 6592.36 | R9: 0 | S9: 19.129038 | T9: =AVERAGE(AQ9:AR9) -> 3.5799744 | U9: =VLOOKUP($AT9,kkk,U$4,0) -> #N/A | V9: =M9+SUM(AG9:AO9)+$T$1+R9/$Z$1 -> 3.1102299 | W9: =M9+SUM(AG9:AO9)+$T$1+R9/$Z$1-AJ9-AM9 -> -1.8135161 | X9: =VLOOKUP($AT9,iii,3,0) -> #N/A | Y9: =VLOOKUP($AT9,iii,2,0) -> #N/A | Z9: =VLOOKUP($AT9,kkk,Z$4,0) -> #N/A | AA9: =VLOOKUP($AT9,kkk,AA$4,0) -> #N/A | AB9: =VLOOKUP($AT9,kkk,AB$4,0) -> #N/A | AC9: =VLOOKUP($AT9,kkk,AC$4,0) -> #N/A | AG9: =C$3*(C$1-C9)/C$2 -> 0.06 | AH9: =D$3*(D$1-D9)/D$2 -> 0 | AI9: =E$3*(E$1-E9)/E$2 -> -0.086904762 | AJ9: =F$3*(F$1-F9)/F$2 -> 4.1896552 | AK9: =G$3*(G$1-G9)/G$2 -> -0.03 | AL9: =H$3*(H$1-H9)/H$2 -> -0.52857143 | AM9: =I$3*(I$1-I9)/I$2 -> 0.73409091 | AN9: =(Q9-$M$1)/$M$2 -> -2.9436989 | AO9: =(J9-$Q$1)/$Q$2 -> -2.0501439 | AQ9: =M9+SUM(AG9:AO9)+$T$1+R9/$Z$1 -> 3.1102299 | AR9: =S9+SUM(AG9:AO9)+$T$1+R9/$Z$1-AJ9-AM9 -> 4.0497188 | AT9: =A9&B9 -> 45413Shift_12
A10: 45413 | B10: Shift_13 | C10: 8.025 | D10: 38.111111 | E10: 26.444444 | F10: 52.64 | G10: 3.94 | H10: 3.3177778 | I10: 149.44444 | J10: 10.262288 | K10: 0.001806692 | L10: 0.018540794 | M10: 13.311707 | N10: 0.0025981205 | O10: 5225 | P10: 118.21965 | Q10: 6592.36 | R10: 0 | S10: 17.414118 | T10: =AVERAGE(AQ10:AR10) -> 2.6386194 | U10: =VLOOKUP($AT10,kkk,U$4,0) -> #N/A | V10: =M10+SUM(AG10:AO10)+$T$1+R10/$Z$1 -> 2.9987819 | W10: =M10+SUM(AG10:AO10)+$T$1+R10/$Z$1-AJ10-AM10 -> -1.8239541 | X10: =VLOOKUP($AT10,iii,3,0) -> #N/A | Y10: =VLOOKUP($AT10,iii,2,0) -> #N/A | Z10: =VLOOKUP($AT10,kkk,Z$4,0) -> #N/A | AA10: =VLOOKUP($AT10,kkk,AA$4,0) -> #N/A | AB10: =VLOOKUP($AT10,kkk,AB$4,0) -> #N/A | AC10: =VLOOKUP($AT10,kkk,AC$4,0) -> #N/A | AG10: =C$3*(C$1-C10)/C$2 -> 0.025 | AH10: =D$3*(D$1-D10)/D$2 -> 0 | AI10: =E$3*(E$1-E10)/E$2 -> -0.19537037 | AJ10: =F$3*(F$1-F10)/F$2 -> 4.1896552 | AK10: =G$3*(G$1-G10)/G$2 -> -0.39 | AL10: =H$3*(H$1-H10)/H$2 -> -0.41111111 | AM10: =I$3*(I$1-I10)/I$2 -> 0.63308081 | AN10: =(Q10-$M$1)/$M$2 -> -2.9436989 | AO10: =(J10-$Q$1)/$Q$2 -> -1.7204806 | AQ10: =M10+SUM(AG10:AO10)+$T$1+R10/$Z$1 -> 2.9987819 | AR10: =S10+SUM(AG10:AO10)+$T$1+R10/$Z$1-AJ10-AM10 -> 2.2784569 | AT10: =A10&B10 -> 45413Shift_13
A11: 45413 | B11: Shift_14 | C11: 8.025 | D11: 38.111111 | E11: 26.444444 | F11: 52.64 | G11: 3.94 | H11: 3.3177778 | I11: 149.44444 | J11: 10.165435 | K11: 0.0031504097 | L11: 0.032025287 | M11: 13.304066 | N11: 0.0025966355 | O11: 5225 | P11: 115.15267 | Q11: 12938.975 | R11: 0 | S11: 17.657317 | T11: =AVERAGE(AQ11:AR11) -> 3.6229995 | U11: =VLOOKUP($AT11,kkk,U$4,0) -> #N/A | V11: =M11+SUM(AG11:AO11)+$T$1+R11/$Z$1 -> 3.8577423 | W11: =M11+SUM(AG11:AO11)+$T$1+R11/$Z$1-AJ11-AM11 -> -0.96499368 | X11: =VLOOKUP($AT11,iii,3,0) -> #N/A | Y11: =VLOOKUP($AT11,iii,2,0) -> #N/A | Z11: =VLOOKUP($AT11,kkk,Z$4,0) -> #N/A | AA11: =VLOOKUP($AT11,kkk,AA$4,0) -> #N/A | AB11: =VLOOKUP($AT11,kkk,AB$4,0) -> #N/A | AC11: =VLOOKUP($AT11,kkk,AC$4,0) -> #N/A | AG11: =C$3*(C$1-C11)/C$2 -> 0.025 | AH11: =D$3*(D$1-D11)/D$2 -> 0 | AI11: =E$3*(E$1-E11)/E$2 -> -0.19537037 | AJ11: =F$3*(F$1-F11)/F$2 -> 4.1896552 | AK11: =G$3*(G$1-G11)/G$2 -> -0.39 | AL11: =H$3*(H$1-H11)/H$2 -> -0.41111111 | AM11: =I$3*(I$1-I11)/I$2 -> 0.63308081 | AN11: =(Q11-$M$1)/$M$2 -> -2.2385195 | AO11: =(J11-$Q$1)/$Q$2 -> -1.5590591 | AQ11: =M11+SUM(AG11:AO11)+$T$1+R11/$Z$1 -> 3.8577423 | AR11: =S11+SUM(AG11:AO11)+$T$1+R11/$Z$1-AJ11-AM11 -> 3.3882566 | AT11: =A11&B11 -> 45413Shift_14
A12: 45413 | B12: Shift_15 | C12: 8.025 | D12: 38.1 | E12: 26.49 | F12: 56.5 | G12: 3.94 | H12: 3.318 | I12: 150.2 | J12: 10.253562 | K12: 0.0037037261 | L12: 0.037976385 | M12: 22.164113 | N12: 1.6949935 | O12: 5225 | P12: 95.866301 | Q12: 16927.48 | R12: 0 | S12: 17.754114 | T12: =AVERAGE(AQ12:AR12) -> 4.9474145 | U12: =VLOOKUP($AT12,kkk,U$4,0) -> #N/A | V12: =M12+SUM(AG12:AO12)+$T$1+R12/$Z$1 -> 6.1503371 | W12: =M12+SUM(AG12:AO12)+$T$1+R12/$Z$1-AJ12-AM12 -> 8.1544907 | X12: =VLOOKUP($AT12,iii,3,0) -> #N/A | Y12: =VLOOKUP($AT12,iii,2,0) -> #N/A | Z12: =VLOOKUP($AT12,kkk,Z$4,0) -> #N/A | AA12: =VLOOKUP($AT12,kkk,AA$4,0) -> #N/A | AB12: =VLOOKUP($AT12,kkk,AB$4,0) -> #N/A | AC12: =VLOOKUP($AT12,kkk,AC$4,0) -> #N/A | AG12: =C$3*(C$1-C12)/C$2 -> 0.025 | AH12: =D$3*(D$1-D12)/D$2 -> 0 | AI12: =E$3*(E$1-E12)/E$2 -> -0.23333333 | AJ12: =F$3*(F$1-F12)/F$2 -> -2.4655172 | AK12: =G$3*(G$1-G12)/G$2 -> -0.39 | AL12: =H$3*(H$1-H12)/H$2 -> -0.41 | AM12: =I$3*(I$1-I12)/I$2 -> 0.46136364 | AN12: =(Q12-$M$1)/$M$2 -> -1.7953522 | AO12: =(J12-$Q$1)/$Q$2 -> -1.7059366 | AQ12: =M12+SUM(AG12:AO12)+$T$1+R12/$Z$1 -> 6.1503371 | AR12: =S12+SUM(AG12:AO12)+$T$1+R12/$Z$1-AJ12-AM12 -> 3.7444919 | AT12: =A12&B12 -> 45413Shift_15
A13: 45413 | B13: Shift_21 | C13: 8.2666667 | D13: 38 | E13: 26.466667 | F13: 56.5 | G13: 3.97 | H13: 3.3644444 | I13: 155.11111 | J13: 9.6936916 | K13: 0.0086689791 | L13: 0.084034409 | M13: 20.447873 | N13: 0.0025877073 | O13: 5225 | P13: 88.750736 | Q13: 38317.803 | R13: 0 | S13: 15.504178 | T13: =AVERAGE(AQ13:AR13) -> 5.8293991 | U13: =VLOOKUP($AT13,kkk,U$4,0) -> #N/A | V13: =M13+SUM(AG13:AO13)+$T$1+R13/$Z$1 -> 6.7410887 | W13: =M13+SUM(AG13:AO13)+$T$1+R13/$Z$1-AJ13-AM13 -> 9.8614039 | X13: =VLOOKUP($AT13,iii,3,0) -> #N/A | Y13: =VLOOKUP($AT13,iii,2,0) -> #N/A | Z13: =VLOOKUP($AT13,kkk,Z$4,0) -> #N/A | AA13: =VLOOKUP($AT13,kkk,AA$4,0) -> #N/A | AB13: =VLOOKUP($AT13,kkk,AB$4,0) -> #N/A | AC13: =VLOOKUP($AT13,kkk,AC$4,0) -> #N/A | AG13: =C$3*(C$1-C13)/C$2 -> -0.023333333 | AH13: =D$3*(D$1-D13)/D$2 -> 0 | AI13: =E$3*(E$1-E13)/E$2 -> -0.21388889 | AJ13: =F$3*(F$1-F13)/F$2 -> -2.4655172 | AK13: =G$3*(G$1-G13)/G$2 -> -0.48 | AL13: =H$3*(H$1-H13)/H$2 -> -0.17777778 | AM13: =I$3*(I$1-I13)/I$2 -> -0.65479798 | AN13: =(Q13-$M$1)/$M$2 -> 0.58135034 | AO13: =(J13-$Q$1)/$Q$2 -> -0.77281926 | AQ13: =M13+SUM(AG13:AO13)+$T$1+R13/$Z$1 -> 6.7410887 | AR13: =S13+SUM(AG13:AO13)+$T$1+R13/$Z$1-AJ13-AM13 -> 4.9177095 | AT13: =A13&B13 -> 45413Shift_21
A14: 45413 | B14: Shift_22 | C14: 8.3125 | D14: 37.9 | E14: 26.57 | F14: 56.5 | G14: 3.97 | H14: 3.356 | I14: 154.7 | J14: 9.4669516 | K14: 0.0090871175 | L14: 0.086027302 | M14: 19.935125 | N14: 0.0025856961 | O14: 5225 | P14: 85.674037 | Q14: 41486.417 | R14: 0 | S14: 15.081048 | T14: =AVERAGE(AQ14:AR14) -> 6.0006455 | U14: =VLOOKUP($AT14,kkk,U$4,0) -> #N/A | V14: =M14+SUM(AG14:AO14)+$T$1+R14/$Z$1 -> 6.9142438 | W14: =M14+SUM(AG14:AO14)+$T$1+R14/$Z$1-AJ14-AM14 -> 9.9411247 | X14: =VLOOKUP($AT14,iii,3,0) -> #N/A | Y14: =VLOOKUP($AT14,iii,2,0) -> #N/A | Z14: =VLOOKUP($AT14,kkk,Z$4,0) -> #N/A | AA14: =VLOOKUP($AT14,kkk,AA$4,0) -> #N/A | AB14: =VLOOKUP($AT14,kkk,AB$4,0) -> #N/A | AC14: =VLOOKUP($AT14,kkk,AC$4,0) -> #N/A | AG14: =C$3*(C$1-C14)/C$2 -> -0.0325 | AH14: =D$3*(D$1-D14)/D$2 -> 0 | AI14: =E$3*(E$1-E14)/E$2 -> -0.3 | AJ14: =F$3*(F$1-F14)/F$2 -> -2.4655172 | AK14: =G$3*(G$1-G14)/G$2 -> -0.48 | AL14: =H$3*(H$1-H14)/H$2 -> -0.22 | AM14: =I$3*(I$1-I14)/I$2 -> -0.56136364 | AN14: =(Q14-$M$1)/$M$2 -> 0.93341851 | AO14: =(J14-$Q$1)/$Q$2 -> -0.3949193 | AQ14: =M14+SUM(AG14:AO14)+$T$1+R14/$Z$1 -> 6.9142438 | AR14: =S14+SUM(AG14:AO14)+$T$1+R14/$Z$1-AJ14-AM14 -> 5.0870471 | AT14: =A14&B14 -> 45413Shift_22
A15: 45413 | B15: Shift_23 | C15: 8.3125 | D15: 38.333333 | E15: 26.468889 | F15: 56.5 | G15: 3.97 | H15: 3.3511111 | I15: 155.44444 | J15: 9.3607146 | K15: 0.010299043 | L15: 0.096406398 | M15: 20.623535 | N15: 0.0025841094 | O15: 5225 | P15: 81.99612 | Q15: 48137.636 | R15: 0 | S15: 15.61591 | T15: =AVERAGE(AQ15:AR15) -> 7.5035861 | U15: =VLOOKUP($AT15,kkk,U$4,0) -> #N/A | V15: =M15+SUM(AG15:AO15)+$T$1+R15/$Z$1 -> 8.4093619 | W15: =M15+SUM(AG15:AO15)+$T$1+R15/$Z$1-AJ15-AM15 -> 11.605435 | X15: =VLOOKUP($AT15,iii,3,0) -> #N/A | Y15: =VLOOKUP($AT15,iii,2,0) -> #N/A | Z15: =VLOOKUP($AT15,kkk,Z$4,0) -> #N/A | AA15: =VLOOKUP($AT15,kkk,AA$4,0) -> #N/A | AB15: =VLOOKUP($AT15,kkk,AB$4,0) -> #N/A | AC15: =VLOOKUP($AT15,kkk,AC$4,0) -> #N/A | AG15: =C$3*(C$1-C15)/C$2 -> -0.0325 | AH15: =D$3*(D$1-D15)/D$2 -> 0 | AI15: =E$3*(E$1-E15)/E$2 -> -0.21574074 | AJ15: =F$3*(F$1-F15)/F$2 -> -2.4655172 | AK15: =G$3*(G$1-G15)/G$2 -> -0.48 | AL15: =H$3*(H$1-H15)/H$2 -> -0.24444444 | AM15: =I$3*(I$1-I15)/I$2 -> -0.73055556 | AN15: =(Q15-$M$1)/$M$2 -> 1.6724429 | AO15: =(J15-$Q$1)/$Q$2 -> -0.21785772 | AQ15: =M15+SUM(AG15:AO15)+$T$1+R15/$Z$1 -> 8.4093619 | AR15: =S15+SUM(AG15:AO15)+$T$1+R15/$Z$1-AJ15-AM15 -> 6.5978102 | AT15: =A15&B15 -> 45413Shift_23
A16: 45414 | B16: Shift_00 | C16: 8.4833333 | D16: 38.25 | E16: 26.54625 | F16: 56.5 | G16: 4.03 | H16: 3.3425 | I16: 156.125 | J16: 9.4288126 | K16: 0.014068135 | L16: 0.13264581 | M16: 19.758258 | N16: 0.0025847545 | O16: 5225 | P16: 84.156979 | Q16: 65953.397 | R16: 0 | S16: 14.605934 | T16: =AVERAGE(AQ16:AR16) -> 8.0329662 | U16: =VLOOKUP($AT16,kkk,U$4,0) -> #N/A | V16: =M16+SUM(AG16:AO16)+$T$1+R16/$Z$1 -> 8.933756 | W16: =M16+SUM(AG16:AO16)+$T$1+R16/$Z$1-AJ16-AM16 -> 12.284501 | X16: =VLOOKUP($AT16,iii,3,0) -> #N/A | Y16: =VLOOKUP($AT16,iii,2,0) -> #N/A | Z16: =VLOOKUP($AT16,kkk,Z$4,0) -> #N/A | AA16: =VLOOKUP($AT16,kkk,AA$4,0) -> #N/A | AB16: =VLOOKUP($AT16,kkk,AB$4,0) -> #N/A | AC16: =VLOOKUP($AT16,kkk,AC$4,0) -> #N/A | AG16: =C$3*(C$1-C16)/C$2 -> -0.066666667 | AH16: =D$3*(D$1-D16)/D$2 -> 0 | AI16: =E$3*(E$1-E16)/E$2 -> -0.28020833 | AJ16: =F$3*(F$1-F16)/F$2 -> -2.4655172 | AK16: =G$3*(G$1-G16)/G$2 -> -0.66 | AL16: =H$3*(H$1-H16)/H$2 -> -0.2875 | AM16: =I$3*(I$1-I16)/I$2 -> -0.88522727 | AN16: =(Q16-$M$1)/$M$2 -> 3.6519719 | AO16: =(J16-$Q$1)/$Q$2 -> -0.33135433 | AQ16: =M16+SUM(AG16:AO16)+$T$1+R16/$Z$1 -> 8.933756 | AR16: =S16+SUM(AG16:AO16)+$T$1+R16/$Z$1-AJ16-AM16 -> 7.1321763 | AT16: =A16&B16 -> 45414Shift_00
